INFO 2021-01-25 23:32:21,081 autoreload 617 Watching for file changes with StatReloader
INFO 2021-01-25 23:33:01,035 autoreload 617 Watching for file changes with StatReloader
INFO 2021-01-25 23:33:08,611 basehttp 157 "GET /admin/ HTTP/1.1" 302 0
INFO 2021-01-25 23:33:08,687 basehttp 157 "GET /admin/login/?next=/admin/ HTTP/1.1" 200 2194
INFO 2021-01-25 23:33:08,770 basehttp 157 "GET /static/admin/css/nav_sidebar.css HTTP/1.1" 200 2138
INFO 2021-01-25 23:33:08,772 basehttp 157 "GET /static/admin/css/base.css HTTP/1.1" 200 16307
INFO 2021-01-25 23:33:08,774 basehttp 157 "GET /static/admin/css/login.css HTTP/1.1" 200 1185
INFO 2021-01-25 23:33:08,775 basehttp 157 "GET /static/admin/js/nav_sidebar.js HTTP/1.1" 200 1360
INFO 2021-01-25 23:33:08,776 basehttp 157 "GET /static/admin/css/responsive.css HTTP/1.1" 200 18339
INFO 2021-01-25 23:33:17,334 basehttp 157 "GET /admin/ HTTP/1.1" 302 0
INFO 2021-01-25 23:33:17,404 basehttp 157 "GET /admin/login/?next=/admin/ HTTP/1.1" 200 2194
INFO 2021-01-25 23:33:18,750 basehttp 157 "GET / HTTP/1.1" 200 16351
INFO 2021-01-25 23:42:35,704 autoreload 240 F:\文档\code\pythonCode\hippo\hippo_api\hippo_api\settings\dev.py changed, reloading.
INFO 2021-01-25 23:42:38,562 autoreload 617 Watching for file changes with StatReloader
INFO 2021-01-25 23:44:52,307 autoreload 240 F:\文档\code\pythonCode\hippo\hippo_api\hippo_api\settings\dev.py changed, reloading.
INFO 2021-01-25 23:44:54,601 autoreload 617 Watching for file changes with StatReloader
INFO 2021-01-25 23:45:18,554 autoreload 240 F:\文档\code\pythonCode\hippo\hippo_api\hippo_api\settings\dev.py changed, reloading.
INFO 2021-01-25 23:45:21,088 autoreload 617 Watching for file changes with StatReloader
INFO 2021-01-25 23:47:22,354 autoreload 240 F:\文档\code\pythonCode\hippo\hippo_api\hippo_api\settings\dev.py changed, reloading.
INFO 2021-01-25 23:47:24,661 autoreload 617 Watching for file changes with StatReloader
INFO 2021-01-25 23:53:31,922 autoreload 240 F:\文档\code\pythonCode\hippo\hippo_api\hippo_api\settings\__init__.py changed, reloading.
INFO 2021-01-25 23:53:34,478 autoreload 617 Watching for file changes with StatReloader
INFO 2021-01-25 23:53:39,668 autoreload 240 F:\文档\code\pythonCode\hippo\hippo_api\hippo_api\settings\__init__.py changed, reloading.
INFO 2021-01-25 23:53:42,012 autoreload 617 Watching for file changes with StatReloader
INFO 2021-01-25 23:54:44,962 autoreload 240 F:\文档\code\pythonCode\hippo\hippo_api\hippo_api\settings\dev.py changed, reloading.
INFO 2021-01-25 23:54:46,964 autoreload 617 Watching for file changes with StatReloader
INFO 2021-01-25 23:55:56,865 autoreload 240 F:\文档\code\pythonCode\hippo\hippo_api\hippo_api\settings\dev.py changed, reloading.
INFO 2021-01-25 23:55:59,253 autoreload 617 Watching for file changes with StatReloader
INFO 2021-01-25 23:56:09,631 autoreload 240 F:\文档\code\pythonCode\hippo\hippo_api\hippo_api\settings\dev.py changed, reloading.
INFO 2021-01-25 23:56:14,669 autoreload 617 Watching for file changes with StatReloader
INFO 2021-01-25 23:56:25,923 basehttp 157 "GET / HTTP/1.1" 200 16351
INFO 2021-01-26 00:07:16,168 basehttp 157 "GET / HTTP/1.1" 200 16351
INFO 2021-01-26 00:07:29,014 basehttp 157 "GET /admin/ HTTP/1.1" 302 0
INFO 2021-01-26 00:07:29,075 basehttp 157 "GET /admin/login/?next=/admin/ HTTP/1.1" 200 2194
INFO 2021-01-26 00:07:33,856 basehttp 157 "POST /admin/login/?next=/admin/ HTTP/1.1" 302 0
INFO 2021-01-26 00:07:33,949 basehttp 157 "GET /admin/ HTTP/1.1" 200 3306
INFO 2021-01-26 00:07:34,013 basehttp 157 "GET /static/admin/css/dashboard.css HTTP/1.1" 200 380
INFO 2021-01-26 00:07:34,030 basehttp 157 "GET /static/admin/img/icon-addlink.svg HTTP/1.1" 200 331
INFO 2021-01-26 00:07:34,033 basehttp 157 "GET /static/admin/img/icon-changelink.svg HTTP/1.1" 200 380
INFO 2021-01-26 00:07:36,158 basehttp 157 "GET /admin/auth/group/add/ HTTP/1.1" 200 7598
INFO 2021-01-26 00:07:36,195 basehttp 157 "GET /static/admin/css/forms.css HTTP/1.1" 200 8423
INFO 2021-01-26 00:07:36,211 basehttp 157 "GET /static/admin/js/jquery.init.js HTTP/1.1" 200 347
INFO 2021-01-26 00:07:36,211 basehttp 157 "GET /static/admin/js/admin/RelatedObjectLookups.js HTTP/1.1" 200 6078
INFO 2021-01-26 00:07:36,212 basehttp 157 "GET /static/admin/js/core.js HTTP/1.1" 200 5418
INFO 2021-01-26 00:07:36,213 basehttp 157 "GET /static/admin/js/SelectBox.js HTTP/1.1" 200 4257
INFO 2021-01-26 00:07:36,217 basehttp 157 "GET /static/admin/js/vendor/jquery/jquery.js HTTP/1.1" 200 287630
INFO 2021-01-26 00:07:36,229 basehttp 157 "GET /static/admin/css/widgets.css HTTP/1.1" 200 10592
INFO 2021-01-26 00:07:36,230 basehttp 157 "GET /static/admin/js/actions.js HTTP/1.1" 200 6783
INFO 2021-01-26 00:07:36,236 basehttp 157 "GET /static/admin/js/prepopulate.js HTTP/1.1" 200 1531
INFO 2021-01-26 00:07:36,237 basehttp 157 "GET /static/admin/js/SelectFilter2.js HTTP/1.1" 200 12350
INFO 2021-01-26 00:07:36,240 basehttp 157 "GET /static/admin/js/urlify.js HTTP/1.1" 200 8632
INFO 2021-01-26 00:07:36,241 basehttp 157 "GET /admin/jsi18n/ HTTP/1.1" 200 3187
INFO 2021-01-26 00:07:36,242 basehttp 157 "GET /static/admin/js/prepopulate_init.js HTTP/1.1" 200 492
INFO 2021-01-26 00:07:36,246 basehttp 157 "GET /static/admin/js/vendor/xregexp/xregexp.js HTTP/1.1" 200 232381
INFO 2021-01-26 00:07:36,253 basehttp 157 "GET /static/admin/js/change_form.js HTTP/1.1" 200 606
INFO 2021-01-26 00:07:36,346 basehttp 157 "GET /static/admin/img/search.svg HTTP/1.1" 200 458
INFO 2021-01-26 00:07:36,347 basehttp 157 "GET /static/admin/img/icon-unknown.svg HTTP/1.1" 200 655
INFO 2021-01-26 00:07:36,349 basehttp 157 "GET /static/admin/img/icon-unknown-alt.svg HTTP/1.1" 200 655
INFO 2021-01-26 00:07:36,350 basehttp 157 "GET /static/admin/img/selector-icons.svg HTTP/1.1" 200 3291
INFO 2021-01-26 00:07:40,820 basehttp 157 "GET /admin/auth/user/add/ HTTP/1.1" 200 6855
INFO 2021-01-26 00:07:40,927 basehttp 157 "GET /admin/jsi18n/ HTTP/1.1" 200 3187
INFO 2021-01-26 00:07:44,341 basehttp 157 "GET /admin/auth/group/add/ HTTP/1.1" 200 7598
INFO 2021-01-26 00:07:44,503 basehttp 157 "GET /admin/jsi18n/ HTTP/1.1" 200 3187
INFO 2021-01-26 00:07:48,400 basehttp 157 "GET /admin/auth/user/add/ HTTP/1.1" 200 6855
INFO 2021-01-26 00:07:48,563 basehttp 157 "GET /admin/jsi18n/ HTTP/1.1" 200 3187
INFO 2021-01-26 00:07:51,132 basehttp 157 "GET /admin/auth/group/add/ HTTP/1.1" 200 7598
INFO 2021-01-26 00:07:51,204 basehttp 157 "GET /admin/jsi18n/ HTTP/1.1" 200 3187
INFO 2021-01-26 00:17:28,661 autoreload 240 F:\文档\code\pythonCode\hippo\hippo_api\hippo_api\apps\users\models.py changed, reloading.
INFO 2021-01-26 00:17:31,342 autoreload 617 Watching for file changes with StatReloader
INFO 2021-01-26 00:20:07,405 autoreload 617 Watching for file changes with StatReloader
INFO 2021-01-26 00:20:22,578 basehttp 157 "GET /admin/ HTTP/1.1" 302 0
INFO 2021-01-26 00:20:22,626 basehttp 157 "GET /admin/login/?next=/admin/ HTTP/1.1" 200 2194
INFO 2021-01-26 00:20:34,667 basehttp 157 "POST /admin/login/?next=/admin/ HTTP/1.1" 302 0
INFO 2021-01-26 00:20:34,820 basehttp 157 "GET /admin/ HTTP/1.1" 200 2902
INFO 2021-01-26 00:20:37,699 basehttp 157 "GET /admin/auth/group/add/ HTTP/1.1" 200 7388
INFO 2021-01-26 00:20:37,804 basehttp 157 "GET /admin/jsi18n/ HTTP/1.1" 200 3187
INFO 2021-01-26 00:44:55,082 basehttp 157 "GET /admin/auth/group/add/ HTTP/1.1" 200 7388
INFO 2021-01-26 00:44:55,128 basehttp 157 "GET /admin/jsi18n/ HTTP/1.1" 200 3187
INFO 2021-01-26 00:44:56,121 basehttp 157 "GET /admin/auth/group/add/ HTTP/1.1" 200 7388
INFO 2021-01-26 00:44:56,188 basehttp 157 "GET /admin/jsi18n/ HTTP/1.1" 200 3187
INFO 2021-01-27 00:04:27,655 autoreload 617 Watching for file changes with StatReloader
INFO 2021-01-27 00:06:22,575 autoreload 240 F:\文档\code\pythonCode\hippo\hippo_api\hippo_api\urls.py changed, reloading.
INFO 2021-01-27 00:06:25,445 autoreload 617 Watching for file changes with StatReloader
INFO 2021-01-27 00:07:02,812 autoreload 617 Watching for file changes with StatReloader
INFO 2021-01-27 00:09:29,302 basehttp 157 "GET /xadmin/ HTTP/1.1" 200 3967
INFO 2021-01-27 00:09:29,394 basehttp 157 "GET /static/xadmin/vendor/bootstrap/css/bootstrap.css HTTP/1.1" 304 0
INFO 2021-01-27 00:09:29,414 basehttp 157 "GET /static/xadmin/css/themes/bootstrap-xadmin.css HTTP/1.1" 304 0
INFO 2021-01-27 00:09:29,423 basehttp 157 "GET /static/xadmin/vendor/font-awesome/css/font-awesome.css HTTP/1.1" 304 0
INFO 2021-01-27 00:09:29,431 basehttp 157 "GET /static/xadmin/css/xadmin.responsive.css HTTP/1.1" 304 0
INFO 2021-01-27 00:09:29,432 basehttp 157 "GET /static/xadmin/vendor/jquery-ui/jquery.ui.core.js HTTP/1.1" 304 0
INFO 2021-01-27 00:09:29,433 basehttp 157 "GET /static/xadmin/vendor/jquery/jquery.js HTTP/1.1" 304 0
INFO 2021-01-27 00:09:29,443 basehttp 157 "GET /static/xadmin/css/xadmin.main.css HTTP/1.1" 304 0
INFO 2021-01-27 00:09:29,448 basehttp 157 "GET /static/xadmin/css/xadmin.plugins.css HTTP/1.1" 304 0
INFO 2021-01-27 00:09:29,456 basehttp 157 "GET /static/xadmin/js/xadmin.main.js HTTP/1.1" 304 0
INFO 2021-01-27 00:09:29,462 basehttp 157 "GET /static/xadmin/vendor/jquery-ui/jquery.ui.mouse.js HTTP/1.1" 304 0
INFO 2021-01-27 00:09:29,463 basehttp 157 "GET /xadmin/jsi18n/ HTTP/1.1" 200 3974
INFO 2021-01-27 00:09:29,467 basehttp 157 "GET /static/xadmin/vendor/jquery-ui/jquery.ui.sortable.js HTTP/1.1" 304 0
INFO 2021-01-27 00:09:29,467 basehttp 157 "GET /static/xadmin/vendor/jquery-ui/jquery.ui.widget.js HTTP/1.1" 304 0
INFO 2021-01-27 00:09:29,468 basehttp 157 "GET /static/xadmin/vendor/bootstrap/js/bootstrap.js HTTP/1.1" 304 0
INFO 2021-01-27 00:09:29,468 basehttp 157 "GET /static/xadmin/js/xadmin.responsive.js HTTP/1.1" 304 0
INFO 2021-01-27 00:09:29,569 basehttp 157 "GET /static/xadmin/vendor/font-awesome/fonts/fontawesome-webfont.woff?v=4.0.3 HTTP/1.1" 304 0
WARNING 2021-01-27 00:09:29,624 log 230 Not Found: /favicon.ico
WARNING 2021-01-27 00:09:29,624 basehttp 157 "GET /favicon.ico HTTP/1.1" 404 1980
INFO 2021-01-27 00:10:04,186 basehttp 157 "POST /xadmin/ HTTP/1.1" 302 0
INFO 2021-01-27 00:10:04,388 basehttp 157 "GET /xadmin/ HTTP/1.1" 200 9942
INFO 2021-01-27 00:10:04,504 basehttp 157 "GET /static/xadmin/js/xadmin.plugin.portal.js HTTP/1.1" 304 0
INFO 2021-01-27 00:10:04,505 basehttp 157 "GET /static/xadmin/css/xadmin.page.dashboard.css HTTP/1.1" 304 0
INFO 2021-01-27 00:10:04,505 basehttp 157 "GET /static/xadmin/js/xadmin.page.dashboard.js HTTP/1.1" 304 0
INFO 2021-01-27 00:10:04,577 basehttp 157 "GET /xadmin/jsi18n/ HTTP/1.1" 200 7732
INFO 2021-01-27 00:16:11,700 basehttp 157 "GET /xadmin/ HTTP/1.1" 200 9942
INFO 2021-01-27 00:16:11,799 basehttp 157 "GET /xadmin/jsi18n/ HTTP/1.1" 200 7732
INFO 2021-01-27 00:16:14,885 basehttp 157 "GET /xadmin/ HTTP/1.1" 200 9942
INFO 2021-01-27 00:16:14,999 basehttp 157 "GET /xadmin/jsi18n/ HTTP/1.1" 200 7732
INFO 2021-01-27 00:16:31,481 autoreload 617 Watching for file changes with StatReloader
INFO 2021-01-27 00:16:39,804 basehttp 157 "GET /xadmin/ HTTP/1.1" 200 13705
INFO 2021-01-27 00:16:39,906 basehttp 157 "GET /static/xadmin/js/xadmin.plugin.themes.js HTTP/1.1" 200 3489
INFO 2021-01-27 00:16:39,910 basehttp 157 "GET /static/xadmin/vendor/jquery-ui/jquery.ui.effect.js HTTP/1.1" 200 31918
INFO 2021-01-27 00:16:39,960 basehttp 157 "GET /xadmin/jsi18n/ HTTP/1.1" 200 7732
ERROR 2021-01-27 00:16:49,630 log 230 Internal Server Error: /xadmin/users/user/
Traceback (most recent call last):
  File "C:\Users\Sunny_Future\AppData\Roaming\Python\Python36\site-packages\django\db\models\options.py", line 575, in get_field
    return self.fields_map[field_name]
KeyError: 'action_checkbox'

During handling of the above exception, another exception occurred:

Traceback (most recent call last):
  File "C:\Users\Sunny_Future\AppData\Roaming\Python\Python36\site-packages\xadmin\views\list.py", line 224, in get_list_queryset
    field = self.opts.get_field(field_name)
  File "C:\Users\Sunny_Future\AppData\Roaming\Python\Python36\site-packages\django\db\models\options.py", line 577, in get_field
    raise FieldDoesNotExist("%s has no field named '%s'" % (self.object_name, field_name))
django.core.exceptions.FieldDoesNotExist: User has no field named 'action_checkbox'

During handling of the above exception, another exception occurred:

Traceback (most recent call last):
  File "C:\Users\Sunny_Future\AppData\Roaming\Python\Python36\site-packages\django\core\handlers\exception.py", line 47, in inner
    response = get_response(request)
  File "C:\Users\Sunny_Future\AppData\Roaming\Python\Python36\site-packages\django\core\handlers\base.py", line 181, in _get_response
    response = wrapped_callback(request, *callback_args, **callback_kwargs)
  File "C:\Users\Sunny_Future\AppData\Roaming\Python\Python36\site-packages\xadmin\sites.py", line 300, in wrapper
    return self.admin_view(view, cacheable)(*args, **kwargs)
  File "C:\Users\Sunny_Future\AppData\Roaming\Python\Python36\site-packages\django\views\decorators\cache.py", line 44, in _wrapped_view_func
    response = view_func(request, *args, **kwargs)
  File "C:\Users\Sunny_Future\AppData\Roaming\Python\Python36\site-packages\xadmin\sites.py", line 208, in inner
    return view(request, *args, **kwargs)
  File "C:\Users\Sunny_Future\AppData\Roaming\Python\Python36\site-packages\xadmin\views\base.py", line 282, in view
    return handler(request, *args, **kwargs)
  File "C:\Users\Sunny_Future\AppData\Roaming\Python\Python36\site-packages\django\utils\decorators.py", line 43, in _wrapper
    return bound_method(*args, **kwargs)
  File "C:\Users\Sunny_Future\AppData\Roaming\Python\Python36\site-packages\django\utils\decorators.py", line 130, in _wrapped_view
    response = view_func(request, *args, **kwargs)
  File "C:\Users\Sunny_Future\AppData\Roaming\Python\Python36\site-packages\xadmin\views\base.py", line 80, in method
    return filter_chain(filters, len(filters) - 1, _inner_method, *args, **kwargs)
  File "C:\Users\Sunny_Future\AppData\Roaming\Python\Python36\site-packages\xadmin\views\base.py", line 49, in filter_chain
    return func()
  File "C:\Users\Sunny_Future\AppData\Roaming\Python\Python36\site-packages\xadmin\views\base.py", line 74, in _inner_method
    return func(self, *args, **kwargs)
  File "C:\Users\Sunny_Future\AppData\Roaming\Python\Python36\site-packages\xadmin\views\list.py", line 401, in get
    response = self.get_result_list()
  File "C:\Users\Sunny_Future\AppData\Roaming\Python\Python36\site-packages\xadmin\views\base.py", line 80, in method
    return filter_chain(filters, len(filters) - 1, _inner_method, *args, **kwargs)
  File "C:\Users\Sunny_Future\AppData\Roaming\Python\Python36\site-packages\xadmin\views\base.py", line 49, in filter_chain
    return func()
  File "C:\Users\Sunny_Future\AppData\Roaming\Python\Python36\site-packages\xadmin\views\base.py", line 74, in _inner_method
    return func(self, *args, **kwargs)
  File "C:\Users\Sunny_Future\AppData\Roaming\Python\Python36\site-packages\xadmin\views\list.py", line 200, in get_result_list
    return self.make_result_list()
  File "C:\Users\Sunny_Future\AppData\Roaming\Python\Python36\site-packages\xadmin\views\list.py", line 172, in make_result_list
    self.list_queryset = self.get_list_queryset()
  File "C:\Users\Sunny_Future\AppData\Roaming\Python\Python36\site-packages\xadmin\views\base.py", line 80, in method
    return filter_chain(filters, len(filters) - 1, _inner_method, *args, **kwargs)
  File "C:\Users\Sunny_Future\AppData\Roaming\Python\Python36\site-packages\xadmin\views\base.py", line 63, in filter_chain
    return filter_chain(filters, token - 1, _inner_method, *args, **kwargs)
  File "C:\Users\Sunny_Future\AppData\Roaming\Python\Python36\site-packages\xadmin\views\base.py", line 49, in filter_chain
    return func()
  File "C:\Users\Sunny_Future\AppData\Roaming\Python\Python36\site-packages\xadmin\views\base.py", line 62, in _inner_method
    return fm(func if fargs[1] == '__' else func(), *args, **kwargs)
  File "C:\Users\Sunny_Future\AppData\Roaming\Python\Python36\site-packages\xadmin\views\base.py", line 74, in _inner_method
    return func(self, *args, **kwargs)
  File "C:\Users\Sunny_Future\AppData\Roaming\Python\Python36\site-packages\xadmin\views\list.py", line 225, in get_list_queryset
    except models.FieldDoesNotExist:
AttributeError: module 'django.db.models' has no attribute 'FieldDoesNotExist'
ERROR 2021-01-27 00:16:49,653 basehttp 157 "GET /xadmin/users/user/ HTTP/1.1" 500 173419
INFO 2021-01-27 00:16:52,975 basehttp 157 "GET /xadmin/ HTTP/1.1" 200 13705
INFO 2021-01-27 00:17:07,288 basehttp 157 "POST /xadmin/settings/user HTTP/1.1" 200 0
INFO 2021-01-27 00:17:07,327 basehttp 157 "GET /static/xadmin/css/themes/bootstrap-theme.css HTTP/1.1" 200 19791
INFO 2021-01-27 00:17:15,813 basehttp 157 "POST /xadmin/settings/user HTTP/1.1" 200 0
INFO 2021-01-27 00:17:25,391 basehttp 157 "POST /xadmin/settings/user HTTP/1.1" 200 0
INFO 2021-01-27 00:17:29,994 basehttp 157 "POST /xadmin/settings/user HTTP/1.1" 200 0
ERROR 2021-01-27 00:19:05,441 log 230 Internal Server Error: /xadmin/users/user/
Traceback (most recent call last):
  File "C:\Users\Sunny_Future\AppData\Roaming\Python\Python36\site-packages\django\db\models\options.py", line 575, in get_field
    return self.fields_map[field_name]
KeyError: 'action_checkbox'

During handling of the above exception, another exception occurred:

Traceback (most recent call last):
  File "C:\Users\Sunny_Future\AppData\Roaming\Python\Python36\site-packages\xadmin\views\list.py", line 224, in get_list_queryset
    field = self.opts.get_field(field_name)
  File "C:\Users\Sunny_Future\AppData\Roaming\Python\Python36\site-packages\django\db\models\options.py", line 577, in get_field
    raise FieldDoesNotExist("%s has no field named '%s'" % (self.object_name, field_name))
django.core.exceptions.FieldDoesNotExist: User has no field named 'action_checkbox'

During handling of the above exception, another exception occurred:

Traceback (most recent call last):
  File "C:\Users\Sunny_Future\AppData\Roaming\Python\Python36\site-packages\django\core\handlers\exception.py", line 47, in inner
    response = get_response(request)
  File "C:\Users\Sunny_Future\AppData\Roaming\Python\Python36\site-packages\django\core\handlers\base.py", line 181, in _get_response
    response = wrapped_callback(request, *callback_args, **callback_kwargs)
  File "C:\Users\Sunny_Future\AppData\Roaming\Python\Python36\site-packages\xadmin\sites.py", line 300, in wrapper
    return self.admin_view(view, cacheable)(*args, **kwargs)
  File "C:\Users\Sunny_Future\AppData\Roaming\Python\Python36\site-packages\django\views\decorators\cache.py", line 44, in _wrapped_view_func
    response = view_func(request, *args, **kwargs)
  File "C:\Users\Sunny_Future\AppData\Roaming\Python\Python36\site-packages\xadmin\sites.py", line 208, in inner
    return view(request, *args, **kwargs)
  File "C:\Users\Sunny_Future\AppData\Roaming\Python\Python36\site-packages\xadmin\views\base.py", line 282, in view
    return handler(request, *args, **kwargs)
  File "C:\Users\Sunny_Future\AppData\Roaming\Python\Python36\site-packages\django\utils\decorators.py", line 43, in _wrapper
    return bound_method(*args, **kwargs)
  File "C:\Users\Sunny_Future\AppData\Roaming\Python\Python36\site-packages\django\utils\decorators.py", line 130, in _wrapped_view
    response = view_func(request, *args, **kwargs)
  File "C:\Users\Sunny_Future\AppData\Roaming\Python\Python36\site-packages\xadmin\views\base.py", line 80, in method
    return filter_chain(filters, len(filters) - 1, _inner_method, *args, **kwargs)
  File "C:\Users\Sunny_Future\AppData\Roaming\Python\Python36\site-packages\xadmin\views\base.py", line 49, in filter_chain
    return func()
  File "C:\Users\Sunny_Future\AppData\Roaming\Python\Python36\site-packages\xadmin\views\base.py", line 74, in _inner_method
    return func(self, *args, **kwargs)
  File "C:\Users\Sunny_Future\AppData\Roaming\Python\Python36\site-packages\xadmin\views\list.py", line 401, in get
    response = self.get_result_list()
  File "C:\Users\Sunny_Future\AppData\Roaming\Python\Python36\site-packages\xadmin\views\base.py", line 80, in method
    return filter_chain(filters, len(filters) - 1, _inner_method, *args, **kwargs)
  File "C:\Users\Sunny_Future\AppData\Roaming\Python\Python36\site-packages\xadmin\views\base.py", line 49, in filter_chain
    return func()
  File "C:\Users\Sunny_Future\AppData\Roaming\Python\Python36\site-packages\xadmin\views\base.py", line 74, in _inner_method
    return func(self, *args, **kwargs)
  File "C:\Users\Sunny_Future\AppData\Roaming\Python\Python36\site-packages\xadmin\views\list.py", line 200, in get_result_list
    return self.make_result_list()
  File "C:\Users\Sunny_Future\AppData\Roaming\Python\Python36\site-packages\xadmin\views\list.py", line 172, in make_result_list
    self.list_queryset = self.get_list_queryset()
  File "C:\Users\Sunny_Future\AppData\Roaming\Python\Python36\site-packages\xadmin\views\base.py", line 80, in method
    return filter_chain(filters, len(filters) - 1, _inner_method, *args, **kwargs)
  File "C:\Users\Sunny_Future\AppData\Roaming\Python\Python36\site-packages\xadmin\views\base.py", line 63, in filter_chain
    return filter_chain(filters, token - 1, _inner_method, *args, **kwargs)
  File "C:\Users\Sunny_Future\AppData\Roaming\Python\Python36\site-packages\xadmin\views\base.py", line 49, in filter_chain
    return func()
  File "C:\Users\Sunny_Future\AppData\Roaming\Python\Python36\site-packages\xadmin\views\base.py", line 62, in _inner_method
    return fm(func if fargs[1] == '__' else func(), *args, **kwargs)
  File "C:\Users\Sunny_Future\AppData\Roaming\Python\Python36\site-packages\xadmin\views\base.py", line 74, in _inner_method
    return func(self, *args, **kwargs)
  File "C:\Users\Sunny_Future\AppData\Roaming\Python\Python36\site-packages\xadmin\views\list.py", line 225, in get_list_queryset
    except models.FieldDoesNotExist:
AttributeError: module 'django.db.models' has no attribute 'FieldDoesNotExist'
ERROR 2021-01-27 00:19:05,460 basehttp 157 "GET /xadmin/users/user/ HTTP/1.1" 500 173694
ERROR 2021-01-27 00:24:47,897 log 230 Internal Server Error: /xadmin/users/user/
Traceback (most recent call last):
  File "C:\Users\Sunny_Future\AppData\Roaming\Python\Python36\site-packages\django\db\models\options.py", line 575, in get_field
    return self.fields_map[field_name]
KeyError: 'action_checkbox'

During handling of the above exception, another exception occurred:

Traceback (most recent call last):
  File "C:\Users\Sunny_Future\AppData\Roaming\Python\Python36\site-packages\xadmin\views\list.py", line 224, in get_list_queryset
    field = self.opts.get_field(field_name)
  File "C:\Users\Sunny_Future\AppData\Roaming\Python\Python36\site-packages\django\db\models\options.py", line 577, in get_field
    raise FieldDoesNotExist("%s has no field named '%s'" % (self.object_name, field_name))
django.core.exceptions.FieldDoesNotExist: User has no field named 'action_checkbox'

During handling of the above exception, another exception occurred:

Traceback (most recent call last):
  File "C:\Users\Sunny_Future\AppData\Roaming\Python\Python36\site-packages\django\core\handlers\exception.py", line 47, in inner
    response = get_response(request)
  File "C:\Users\Sunny_Future\AppData\Roaming\Python\Python36\site-packages\django\core\handlers\base.py", line 181, in _get_response
    response = wrapped_callback(request, *callback_args, **callback_kwargs)
  File "C:\Users\Sunny_Future\AppData\Roaming\Python\Python36\site-packages\xadmin\sites.py", line 300, in wrapper
    return self.admin_view(view, cacheable)(*args, **kwargs)
  File "C:\Users\Sunny_Future\AppData\Roaming\Python\Python36\site-packages\django\views\decorators\cache.py", line 44, in _wrapped_view_func
    response = view_func(request, *args, **kwargs)
  File "C:\Users\Sunny_Future\AppData\Roaming\Python\Python36\site-packages\xadmin\sites.py", line 208, in inner
    return view(request, *args, **kwargs)
  File "C:\Users\Sunny_Future\AppData\Roaming\Python\Python36\site-packages\xadmin\views\base.py", line 282, in view
    return handler(request, *args, **kwargs)
  File "C:\Users\Sunny_Future\AppData\Roaming\Python\Python36\site-packages\django\utils\decorators.py", line 43, in _wrapper
    return bound_method(*args, **kwargs)
  File "C:\Users\Sunny_Future\AppData\Roaming\Python\Python36\site-packages\django\utils\decorators.py", line 130, in _wrapped_view
    response = view_func(request, *args, **kwargs)
  File "C:\Users\Sunny_Future\AppData\Roaming\Python\Python36\site-packages\xadmin\views\base.py", line 80, in method
    return filter_chain(filters, len(filters) - 1, _inner_method, *args, **kwargs)
  File "C:\Users\Sunny_Future\AppData\Roaming\Python\Python36\site-packages\xadmin\views\base.py", line 49, in filter_chain
    return func()
  File "C:\Users\Sunny_Future\AppData\Roaming\Python\Python36\site-packages\xadmin\views\base.py", line 74, in _inner_method
    return func(self, *args, **kwargs)
  File "C:\Users\Sunny_Future\AppData\Roaming\Python\Python36\site-packages\xadmin\views\list.py", line 401, in get
    response = self.get_result_list()
  File "C:\Users\Sunny_Future\AppData\Roaming\Python\Python36\site-packages\xadmin\views\base.py", line 80, in method
    return filter_chain(filters, len(filters) - 1, _inner_method, *args, **kwargs)
  File "C:\Users\Sunny_Future\AppData\Roaming\Python\Python36\site-packages\xadmin\views\base.py", line 49, in filter_chain
    return func()
  File "C:\Users\Sunny_Future\AppData\Roaming\Python\Python36\site-packages\xadmin\views\base.py", line 74, in _inner_method
    return func(self, *args, **kwargs)
  File "C:\Users\Sunny_Future\AppData\Roaming\Python\Python36\site-packages\xadmin\views\list.py", line 200, in get_result_list
    return self.make_result_list()
  File "C:\Users\Sunny_Future\AppData\Roaming\Python\Python36\site-packages\xadmin\views\list.py", line 172, in make_result_list
    self.list_queryset = self.get_list_queryset()
  File "C:\Users\Sunny_Future\AppData\Roaming\Python\Python36\site-packages\xadmin\views\base.py", line 80, in method
    return filter_chain(filters, len(filters) - 1, _inner_method, *args, **kwargs)
  File "C:\Users\Sunny_Future\AppData\Roaming\Python\Python36\site-packages\xadmin\views\base.py", line 63, in filter_chain
    return filter_chain(filters, token - 1, _inner_method, *args, **kwargs)
  File "C:\Users\Sunny_Future\AppData\Roaming\Python\Python36\site-packages\xadmin\views\base.py", line 49, in filter_chain
    return func()
  File "C:\Users\Sunny_Future\AppData\Roaming\Python\Python36\site-packages\xadmin\views\base.py", line 62, in _inner_method
    return fm(func if fargs[1] == '__' else func(), *args, **kwargs)
  File "C:\Users\Sunny_Future\AppData\Roaming\Python\Python36\site-packages\xadmin\views\base.py", line 74, in _inner_method
    return func(self, *args, **kwargs)
  File "C:\Users\Sunny_Future\AppData\Roaming\Python\Python36\site-packages\xadmin\views\list.py", line 225, in get_list_queryset
    except models.FieldDoesNotExist:
AttributeError: module 'django.db.models' has no attribute 'FieldDoesNotExist'
ERROR 2021-01-27 00:24:47,906 basehttp 157 "GET /xadmin/users/user/ HTTP/1.1" 500 173676
WARNING 2021-01-27 00:25:02,407 log 230 Not Found: /xadmin/users/
WARNING 2021-01-27 00:25:02,407 basehttp 157 "GET /xadmin/users/ HTTP/1.1" 404 5994
INFO 2021-01-27 00:25:19,719 basehttp 157 "GET /xadmin/ HTTP/1.1" 200 13710
INFO 2021-01-27 00:25:19,857 basehttp 157 "GET /xadmin/jsi18n/ HTTP/1.1" 200 7732
ERROR 2021-01-27 00:25:25,161 log 230 Internal Server Error: /xadmin/users/user/
Traceback (most recent call last):
  File "C:\Users\Sunny_Future\AppData\Roaming\Python\Python36\site-packages\django\db\models\options.py", line 575, in get_field
    return self.fields_map[field_name]
KeyError: 'action_checkbox'

During handling of the above exception, another exception occurred:

Traceback (most recent call last):
  File "C:\Users\Sunny_Future\AppData\Roaming\Python\Python36\site-packages\xadmin\views\list.py", line 224, in get_list_queryset
    field = self.opts.get_field(field_name)
  File "C:\Users\Sunny_Future\AppData\Roaming\Python\Python36\site-packages\django\db\models\options.py", line 577, in get_field
    raise FieldDoesNotExist("%s has no field named '%s'" % (self.object_name, field_name))
django.core.exceptions.FieldDoesNotExist: User has no field named 'action_checkbox'

During handling of the above exception, another exception occurred:

Traceback (most recent call last):
  File "C:\Users\Sunny_Future\AppData\Roaming\Python\Python36\site-packages\django\core\handlers\exception.py", line 47, in inner
    response = get_response(request)
  File "C:\Users\Sunny_Future\AppData\Roaming\Python\Python36\site-packages\django\core\handlers\base.py", line 181, in _get_response
    response = wrapped_callback(request, *callback_args, **callback_kwargs)
  File "C:\Users\Sunny_Future\AppData\Roaming\Python\Python36\site-packages\xadmin\sites.py", line 300, in wrapper
    return self.admin_view(view, cacheable)(*args, **kwargs)
  File "C:\Users\Sunny_Future\AppData\Roaming\Python\Python36\site-packages\django\views\decorators\cache.py", line 44, in _wrapped_view_func
    response = view_func(request, *args, **kwargs)
  File "C:\Users\Sunny_Future\AppData\Roaming\Python\Python36\site-packages\xadmin\sites.py", line 208, in inner
    return view(request, *args, **kwargs)
  File "C:\Users\Sunny_Future\AppData\Roaming\Python\Python36\site-packages\xadmin\views\base.py", line 282, in view
    return handler(request, *args, **kwargs)
  File "C:\Users\Sunny_Future\AppData\Roaming\Python\Python36\site-packages\django\utils\decorators.py", line 43, in _wrapper
    return bound_method(*args, **kwargs)
  File "C:\Users\Sunny_Future\AppData\Roaming\Python\Python36\site-packages\django\utils\decorators.py", line 130, in _wrapped_view
    response = view_func(request, *args, **kwargs)
  File "C:\Users\Sunny_Future\AppData\Roaming\Python\Python36\site-packages\xadmin\views\base.py", line 80, in method
    return filter_chain(filters, len(filters) - 1, _inner_method, *args, **kwargs)
  File "C:\Users\Sunny_Future\AppData\Roaming\Python\Python36\site-packages\xadmin\views\base.py", line 49, in filter_chain
    return func()
  File "C:\Users\Sunny_Future\AppData\Roaming\Python\Python36\site-packages\xadmin\views\base.py", line 74, in _inner_method
    return func(self, *args, **kwargs)
  File "C:\Users\Sunny_Future\AppData\Roaming\Python\Python36\site-packages\xadmin\views\list.py", line 401, in get
    response = self.get_result_list()
  File "C:\Users\Sunny_Future\AppData\Roaming\Python\Python36\site-packages\xadmin\views\base.py", line 80, in method
    return filter_chain(filters, len(filters) - 1, _inner_method, *args, **kwargs)
  File "C:\Users\Sunny_Future\AppData\Roaming\Python\Python36\site-packages\xadmin\views\base.py", line 49, in filter_chain
    return func()
  File "C:\Users\Sunny_Future\AppData\Roaming\Python\Python36\site-packages\xadmin\views\base.py", line 74, in _inner_method
    return func(self, *args, **kwargs)
  File "C:\Users\Sunny_Future\AppData\Roaming\Python\Python36\site-packages\xadmin\views\list.py", line 200, in get_result_list
    return self.make_result_list()
  File "C:\Users\Sunny_Future\AppData\Roaming\Python\Python36\site-packages\xadmin\views\list.py", line 172, in make_result_list
    self.list_queryset = self.get_list_queryset()
  File "C:\Users\Sunny_Future\AppData\Roaming\Python\Python36\site-packages\xadmin\views\base.py", line 80, in method
    return filter_chain(filters, len(filters) - 1, _inner_method, *args, **kwargs)
  File "C:\Users\Sunny_Future\AppData\Roaming\Python\Python36\site-packages\xadmin\views\base.py", line 63, in filter_chain
    return filter_chain(filters, token - 1, _inner_method, *args, **kwargs)
  File "C:\Users\Sunny_Future\AppData\Roaming\Python\Python36\site-packages\xadmin\views\base.py", line 49, in filter_chain
    return func()
  File "C:\Users\Sunny_Future\AppData\Roaming\Python\Python36\site-packages\xadmin\views\base.py", line 62, in _inner_method
    return fm(func if fargs[1] == '__' else func(), *args, **kwargs)
  File "C:\Users\Sunny_Future\AppData\Roaming\Python\Python36\site-packages\xadmin\views\base.py", line 74, in _inner_method
    return func(self, *args, **kwargs)
  File "C:\Users\Sunny_Future\AppData\Roaming\Python\Python36\site-packages\xadmin\views\list.py", line 225, in get_list_queryset
    except models.FieldDoesNotExist:
AttributeError: module 'django.db.models' has no attribute 'FieldDoesNotExist'
ERROR 2021-01-27 00:25:25,168 basehttp 157 "GET /xadmin/users/user/ HTTP/1.1" 500 173694
INFO 2021-01-27 00:28:28,864 autoreload 617 Watching for file changes with StatReloader
ERROR 2021-01-27 00:28:37,003 log 230 Internal Server Error: /xadmin/users/user/
Traceback (most recent call last):
  File "C:\Users\Sunny_Future\AppData\Roaming\Python\Python36\site-packages\django\db\models\options.py", line 575, in get_field
    return self.fields_map[field_name]
KeyError: 'action_checkbox'

During handling of the above exception, another exception occurred:

Traceback (most recent call last):
  File "C:\Users\Sunny_Future\AppData\Roaming\Python\Python36\site-packages\xadmin\views\list.py", line 224, in get_list_queryset
    field = self.opts.get_field(field_name)
  File "C:\Users\Sunny_Future\AppData\Roaming\Python\Python36\site-packages\django\db\models\options.py", line 577, in get_field
    raise FieldDoesNotExist("%s has no field named '%s'" % (self.object_name, field_name))
django.core.exceptions.FieldDoesNotExist: User has no field named 'action_checkbox'

During handling of the above exception, another exception occurred:

Traceback (most recent call last):
  File "C:\Users\Sunny_Future\AppData\Roaming\Python\Python36\site-packages\django\core\handlers\exception.py", line 47, in inner
    response = get_response(request)
  File "C:\Users\Sunny_Future\AppData\Roaming\Python\Python36\site-packages\django\core\handlers\base.py", line 181, in _get_response
    response = wrapped_callback(request, *callback_args, **callback_kwargs)
  File "C:\Users\Sunny_Future\AppData\Roaming\Python\Python36\site-packages\xadmin\sites.py", line 300, in wrapper
    return self.admin_view(view, cacheable)(*args, **kwargs)
  File "C:\Users\Sunny_Future\AppData\Roaming\Python\Python36\site-packages\django\views\decorators\cache.py", line 44, in _wrapped_view_func
    response = view_func(request, *args, **kwargs)
  File "C:\Users\Sunny_Future\AppData\Roaming\Python\Python36\site-packages\xadmin\sites.py", line 208, in inner
    return view(request, *args, **kwargs)
  File "C:\Users\Sunny_Future\AppData\Roaming\Python\Python36\site-packages\xadmin\views\base.py", line 282, in view
    return handler(request, *args, **kwargs)
  File "C:\Users\Sunny_Future\AppData\Roaming\Python\Python36\site-packages\django\utils\decorators.py", line 43, in _wrapper
    return bound_method(*args, **kwargs)
  File "C:\Users\Sunny_Future\AppData\Roaming\Python\Python36\site-packages\django\utils\decorators.py", line 130, in _wrapped_view
    response = view_func(request, *args, **kwargs)
  File "C:\Users\Sunny_Future\AppData\Roaming\Python\Python36\site-packages\xadmin\views\base.py", line 80, in method
    return filter_chain(filters, len(filters) - 1, _inner_method, *args, **kwargs)
  File "C:\Users\Sunny_Future\AppData\Roaming\Python\Python36\site-packages\xadmin\views\base.py", line 49, in filter_chain
    return func()
  File "C:\Users\Sunny_Future\AppData\Roaming\Python\Python36\site-packages\xadmin\views\base.py", line 74, in _inner_method
    return func(self, *args, **kwargs)
  File "C:\Users\Sunny_Future\AppData\Roaming\Python\Python36\site-packages\xadmin\views\list.py", line 401, in get
    response = self.get_result_list()
  File "C:\Users\Sunny_Future\AppData\Roaming\Python\Python36\site-packages\xadmin\views\base.py", line 80, in method
    return filter_chain(filters, len(filters) - 1, _inner_method, *args, **kwargs)
  File "C:\Users\Sunny_Future\AppData\Roaming\Python\Python36\site-packages\xadmin\views\base.py", line 49, in filter_chain
    return func()
  File "C:\Users\Sunny_Future\AppData\Roaming\Python\Python36\site-packages\xadmin\views\base.py", line 74, in _inner_method
    return func(self, *args, **kwargs)
  File "C:\Users\Sunny_Future\AppData\Roaming\Python\Python36\site-packages\xadmin\views\list.py", line 200, in get_result_list
    return self.make_result_list()
  File "C:\Users\Sunny_Future\AppData\Roaming\Python\Python36\site-packages\xadmin\views\list.py", line 172, in make_result_list
    self.list_queryset = self.get_list_queryset()
  File "C:\Users\Sunny_Future\AppData\Roaming\Python\Python36\site-packages\xadmin\views\base.py", line 80, in method
    return filter_chain(filters, len(filters) - 1, _inner_method, *args, **kwargs)
  File "C:\Users\Sunny_Future\AppData\Roaming\Python\Python36\site-packages\xadmin\views\base.py", line 63, in filter_chain
    return filter_chain(filters, token - 1, _inner_method, *args, **kwargs)
  File "C:\Users\Sunny_Future\AppData\Roaming\Python\Python36\site-packages\xadmin\views\base.py", line 49, in filter_chain
    return func()
  File "C:\Users\Sunny_Future\AppData\Roaming\Python\Python36\site-packages\xadmin\views\base.py", line 62, in _inner_method
    return fm(func if fargs[1] == '__' else func(), *args, **kwargs)
  File "C:\Users\Sunny_Future\AppData\Roaming\Python\Python36\site-packages\xadmin\views\base.py", line 74, in _inner_method
    return func(self, *args, **kwargs)
  File "C:\Users\Sunny_Future\AppData\Roaming\Python\Python36\site-packages\xadmin\views\list.py", line 225, in get_list_queryset
    except models.FieldDoesNotExist:
AttributeError: module 'django.db.models' has no attribute 'FieldDoesNotExist'
ERROR 2021-01-27 00:28:37,019 basehttp 157 "GET /xadmin/users/user/ HTTP/1.1" 500 173676
INFO 2021-01-27 00:32:50,050 autoreload 240 F:\文档\code\pythonCode\hippo\hippo_api\hippo_api\urls.py changed, reloading.
INFO 2021-01-27 00:32:53,293 autoreload 617 Watching for file changes with StatReloader
INFO 2021-01-27 22:23:24,872 autoreload 617 Watching for file changes with StatReloader
INFO 2021-01-27 22:34:49,057 autoreload 617 Watching for file changes with StatReloader
INFO 2021-01-27 22:35:23,114 basehttp 157 "GET /xadmin/ HTTP/1.1" 200 13710
INFO 2021-01-27 22:35:23,141 basehttp 157 "GET /static/xadmin/vendor/bootstrap/css/bootstrap.css HTTP/1.1" 304 0
INFO 2021-01-27 22:35:23,145 basehttp 157 "GET /static/xadmin/vendor/font-awesome/css/font-awesome.css HTTP/1.1" 304 0
INFO 2021-01-27 22:35:23,149 basehttp 157 "GET /static/xadmin/css/xadmin.main.css HTTP/1.1" 304 0
INFO 2021-01-27 22:35:23,152 basehttp 157 "GET /static/xadmin/css/xadmin.responsive.css HTTP/1.1" 304 0
INFO 2021-01-27 22:35:23,155 basehttp 157 "GET /static/xadmin/css/xadmin.plugins.css HTTP/1.1" 304 0
INFO 2021-01-27 22:35:23,156 basehttp 157 "GET /static/xadmin/css/xadmin.page.dashboard.css HTTP/1.1" 304 0
INFO 2021-01-27 22:35:23,158 basehttp 157 "GET /static/xadmin/vendor/jquery/jquery.js HTTP/1.1" 304 0
INFO 2021-01-27 22:35:23,159 basehttp 157 "GET /static/xadmin/vendor/jquery-ui/jquery.ui.widget.js HTTP/1.1" 304 0
INFO 2021-01-27 22:35:23,159 basehttp 157 "GET /static/xadmin/vendor/jquery-ui/jquery.ui.core.js HTTP/1.1" 304 0
INFO 2021-01-27 22:35:23,160 basehttp 157 "GET /static/xadmin/js/xadmin.main.js HTTP/1.1" 304 0
INFO 2021-01-27 22:35:23,162 basehttp 157 "GET /static/xadmin/vendor/jquery-ui/jquery.ui.mouse.js HTTP/1.1" 304 0
INFO 2021-01-27 22:35:23,167 basehttp 157 "GET /static/xadmin/vendor/jquery-ui/jquery.ui.sortable.js HTTP/1.1" 304 0
INFO 2021-01-27 22:35:23,167 basehttp 157 "GET /static/xadmin/vendor/bootstrap/js/bootstrap.js HTTP/1.1" 304 0
INFO 2021-01-27 22:35:23,168 basehttp 157 "GET /static/xadmin/vendor/jquery-ui/jquery.ui.effect.js HTTP/1.1" 304 0
INFO 2021-01-27 22:35:23,170 basehttp 157 "GET /static/xadmin/js/xadmin.page.dashboard.js HTTP/1.1" 304 0
INFO 2021-01-27 22:35:23,171 basehttp 157 "GET /static/xadmin/js/xadmin.responsive.js HTTP/1.1" 304 0
INFO 2021-01-27 22:35:23,173 basehttp 157 "GET /static/xadmin/js/xadmin.plugin.portal.js HTTP/1.1" 304 0
INFO 2021-01-27 22:35:23,173 basehttp 157 "GET /static/xadmin/js/xadmin.plugin.themes.js HTTP/1.1" 304 0
INFO 2021-01-27 22:35:23,176 basehttp 157 "GET /xadmin/jsi18n/ HTTP/1.1" 200 7732
INFO 2021-01-27 22:35:25,462 basehttp 157 "GET /static/xadmin/vendor/font-awesome/fonts/fontawesome-webfont.woff?v=4.0.3 HTTP/1.1" 304 0
ERROR 2021-01-27 22:35:29,969 log 230 Internal Server Error: /xadmin/users/user/
Traceback (most recent call last):
  File "C:\Users\Sunny_Future\AppData\Roaming\Python\Python36\site-packages\django\db\models\options.py", line 575, in get_field
    return self.fields_map[field_name]
KeyError: 'action_checkbox'

During handling of the above exception, another exception occurred:

Traceback (most recent call last):
  File "C:\Users\Sunny_Future\AppData\Roaming\Python\Python36\site-packages\xadmin\views\list.py", line 224, in get_list_queryset
    field = self.opts.get_field(field_name)
  File "C:\Users\Sunny_Future\AppData\Roaming\Python\Python36\site-packages\django\db\models\options.py", line 577, in get_field
    raise FieldDoesNotExist("%s has no field named '%s'" % (self.object_name, field_name))
django.core.exceptions.FieldDoesNotExist: User has no field named 'action_checkbox'

During handling of the above exception, another exception occurred:

Traceback (most recent call last):
  File "C:\Users\Sunny_Future\AppData\Roaming\Python\Python36\site-packages\django\core\handlers\exception.py", line 47, in inner
    response = get_response(request)
  File "C:\Users\Sunny_Future\AppData\Roaming\Python\Python36\site-packages\django\core\handlers\base.py", line 181, in _get_response
    response = wrapped_callback(request, *callback_args, **callback_kwargs)
  File "C:\Users\Sunny_Future\AppData\Roaming\Python\Python36\site-packages\xadmin\sites.py", line 300, in wrapper
    return self.admin_view(view, cacheable)(*args, **kwargs)
  File "C:\Users\Sunny_Future\AppData\Roaming\Python\Python36\site-packages\django\views\decorators\cache.py", line 44, in _wrapped_view_func
    response = view_func(request, *args, **kwargs)
  File "C:\Users\Sunny_Future\AppData\Roaming\Python\Python36\site-packages\xadmin\sites.py", line 208, in inner
    return view(request, *args, **kwargs)
  File "C:\Users\Sunny_Future\AppData\Roaming\Python\Python36\site-packages\xadmin\views\base.py", line 282, in view
    return handler(request, *args, **kwargs)
  File "C:\Users\Sunny_Future\AppData\Roaming\Python\Python36\site-packages\django\utils\decorators.py", line 43, in _wrapper
    return bound_method(*args, **kwargs)
  File "C:\Users\Sunny_Future\AppData\Roaming\Python\Python36\site-packages\django\utils\decorators.py", line 130, in _wrapped_view
    response = view_func(request, *args, **kwargs)
  File "C:\Users\Sunny_Future\AppData\Roaming\Python\Python36\site-packages\xadmin\views\base.py", line 80, in method
    return filter_chain(filters, len(filters) - 1, _inner_method, *args, **kwargs)
  File "C:\Users\Sunny_Future\AppData\Roaming\Python\Python36\site-packages\xadmin\views\base.py", line 49, in filter_chain
    return func()
  File "C:\Users\Sunny_Future\AppData\Roaming\Python\Python36\site-packages\xadmin\views\base.py", line 74, in _inner_method
    return func(self, *args, **kwargs)
  File "C:\Users\Sunny_Future\AppData\Roaming\Python\Python36\site-packages\xadmin\views\list.py", line 401, in get
    response = self.get_result_list()
  File "C:\Users\Sunny_Future\AppData\Roaming\Python\Python36\site-packages\xadmin\views\base.py", line 80, in method
    return filter_chain(filters, len(filters) - 1, _inner_method, *args, **kwargs)
  File "C:\Users\Sunny_Future\AppData\Roaming\Python\Python36\site-packages\xadmin\views\base.py", line 49, in filter_chain
    return func()
  File "C:\Users\Sunny_Future\AppData\Roaming\Python\Python36\site-packages\xadmin\views\base.py", line 74, in _inner_method
    return func(self, *args, **kwargs)
  File "C:\Users\Sunny_Future\AppData\Roaming\Python\Python36\site-packages\xadmin\views\list.py", line 200, in get_result_list
    return self.make_result_list()
  File "C:\Users\Sunny_Future\AppData\Roaming\Python\Python36\site-packages\xadmin\views\list.py", line 172, in make_result_list
    self.list_queryset = self.get_list_queryset()
  File "C:\Users\Sunny_Future\AppData\Roaming\Python\Python36\site-packages\xadmin\views\base.py", line 80, in method
    return filter_chain(filters, len(filters) - 1, _inner_method, *args, **kwargs)
  File "C:\Users\Sunny_Future\AppData\Roaming\Python\Python36\site-packages\xadmin\views\base.py", line 63, in filter_chain
    return filter_chain(filters, token - 1, _inner_method, *args, **kwargs)
  File "C:\Users\Sunny_Future\AppData\Roaming\Python\Python36\site-packages\xadmin\views\base.py", line 49, in filter_chain
    return func()
  File "C:\Users\Sunny_Future\AppData\Roaming\Python\Python36\site-packages\xadmin\views\base.py", line 62, in _inner_method
    return fm(func if fargs[1] == '__' else func(), *args, **kwargs)
  File "C:\Users\Sunny_Future\AppData\Roaming\Python\Python36\site-packages\xadmin\views\base.py", line 74, in _inner_method
    return func(self, *args, **kwargs)
  File "C:\Users\Sunny_Future\AppData\Roaming\Python\Python36\site-packages\xadmin\views\list.py", line 225, in get_list_queryset
    except models.FieldDoesNotExist:
AttributeError: module 'django.db.models' has no attribute 'FieldDoesNotExist'
ERROR 2021-01-27 22:35:29,973 basehttp 157 "GET /xadmin/users/user/ HTTP/1.1" 500 173778
INFO 2021-01-27 22:41:18,082 basehttp 157 "GET /xadmin/ HTTP/1.1" 200 13710
INFO 2021-01-27 22:41:18,118 basehttp 157 "GET /xadmin/jsi18n/ HTTP/1.1" 200 7732
INFO 2021-01-27 22:41:19,285 basehttp 157 "GET /xadmin/ HTTP/1.1" 200 13710
ERROR 2021-01-27 22:41:24,367 log 230 Internal Server Error: /xadmin/users/user/
Traceback (most recent call last):
  File "C:\Users\Sunny_Future\AppData\Roaming\Python\Python36\site-packages\django\db\models\options.py", line 575, in get_field
    return self.fields_map[field_name]
KeyError: 'action_checkbox'

During handling of the above exception, another exception occurred:

Traceback (most recent call last):
  File "C:\Users\Sunny_Future\AppData\Roaming\Python\Python36\site-packages\xadmin\views\list.py", line 224, in get_list_queryset
    field = self.opts.get_field(field_name)
  File "C:\Users\Sunny_Future\AppData\Roaming\Python\Python36\site-packages\django\db\models\options.py", line 577, in get_field
    raise FieldDoesNotExist("%s has no field named '%s'" % (self.object_name, field_name))
django.core.exceptions.FieldDoesNotExist: User has no field named 'action_checkbox'

During handling of the above exception, another exception occurred:

Traceback (most recent call last):
  File "C:\Users\Sunny_Future\AppData\Roaming\Python\Python36\site-packages\django\core\handlers\exception.py", line 47, in inner
    response = get_response(request)
  File "C:\Users\Sunny_Future\AppData\Roaming\Python\Python36\site-packages\django\core\handlers\base.py", line 181, in _get_response
    response = wrapped_callback(request, *callback_args, **callback_kwargs)
  File "C:\Users\Sunny_Future\AppData\Roaming\Python\Python36\site-packages\xadmin\sites.py", line 300, in wrapper
    return self.admin_view(view, cacheable)(*args, **kwargs)
  File "C:\Users\Sunny_Future\AppData\Roaming\Python\Python36\site-packages\django\views\decorators\cache.py", line 44, in _wrapped_view_func
    response = view_func(request, *args, **kwargs)
  File "C:\Users\Sunny_Future\AppData\Roaming\Python\Python36\site-packages\xadmin\sites.py", line 208, in inner
    return view(request, *args, **kwargs)
  File "C:\Users\Sunny_Future\AppData\Roaming\Python\Python36\site-packages\xadmin\views\base.py", line 282, in view
    return handler(request, *args, **kwargs)
  File "C:\Users\Sunny_Future\AppData\Roaming\Python\Python36\site-packages\django\utils\decorators.py", line 43, in _wrapper
    return bound_method(*args, **kwargs)
  File "C:\Users\Sunny_Future\AppData\Roaming\Python\Python36\site-packages\django\utils\decorators.py", line 130, in _wrapped_view
    response = view_func(request, *args, **kwargs)
  File "C:\Users\Sunny_Future\AppData\Roaming\Python\Python36\site-packages\xadmin\views\base.py", line 80, in method
    return filter_chain(filters, len(filters) - 1, _inner_method, *args, **kwargs)
  File "C:\Users\Sunny_Future\AppData\Roaming\Python\Python36\site-packages\xadmin\views\base.py", line 49, in filter_chain
    return func()
  File "C:\Users\Sunny_Future\AppData\Roaming\Python\Python36\site-packages\xadmin\views\base.py", line 74, in _inner_method
    return func(self, *args, **kwargs)
  File "C:\Users\Sunny_Future\AppData\Roaming\Python\Python36\site-packages\xadmin\views\list.py", line 401, in get
    response = self.get_result_list()
  File "C:\Users\Sunny_Future\AppData\Roaming\Python\Python36\site-packages\xadmin\views\base.py", line 80, in method
    return filter_chain(filters, len(filters) - 1, _inner_method, *args, **kwargs)
  File "C:\Users\Sunny_Future\AppData\Roaming\Python\Python36\site-packages\xadmin\views\base.py", line 49, in filter_chain
    return func()
  File "C:\Users\Sunny_Future\AppData\Roaming\Python\Python36\site-packages\xadmin\views\base.py", line 74, in _inner_method
    return func(self, *args, **kwargs)
  File "C:\Users\Sunny_Future\AppData\Roaming\Python\Python36\site-packages\xadmin\views\list.py", line 200, in get_result_list
    return self.make_result_list()
  File "C:\Users\Sunny_Future\AppData\Roaming\Python\Python36\site-packages\xadmin\views\list.py", line 172, in make_result_list
    self.list_queryset = self.get_list_queryset()
  File "C:\Users\Sunny_Future\AppData\Roaming\Python\Python36\site-packages\xadmin\views\base.py", line 80, in method
    return filter_chain(filters, len(filters) - 1, _inner_method, *args, **kwargs)
  File "C:\Users\Sunny_Future\AppData\Roaming\Python\Python36\site-packages\xadmin\views\base.py", line 63, in filter_chain
    return filter_chain(filters, token - 1, _inner_method, *args, **kwargs)
  File "C:\Users\Sunny_Future\AppData\Roaming\Python\Python36\site-packages\xadmin\views\base.py", line 49, in filter_chain
    return func()
  File "C:\Users\Sunny_Future\AppData\Roaming\Python\Python36\site-packages\xadmin\views\base.py", line 62, in _inner_method
    return fm(func if fargs[1] == '__' else func(), *args, **kwargs)
  File "C:\Users\Sunny_Future\AppData\Roaming\Python\Python36\site-packages\xadmin\views\base.py", line 74, in _inner_method
    return func(self, *args, **kwargs)
  File "C:\Users\Sunny_Future\AppData\Roaming\Python\Python36\site-packages\xadmin\views\list.py", line 225, in get_list_queryset
    except models.FieldDoesNotExist:
AttributeError: module 'django.db.models' has no attribute 'FieldDoesNotExist'
ERROR 2021-01-27 22:41:24,373 basehttp 157 "GET /xadmin/users/user/ HTTP/1.1" 500 173778
INFO 2021-01-27 22:41:25,941 basehttp 157 "GET /xadmin/ HTTP/1.1" 200 13710
ERROR 2021-01-27 22:41:28,449 log 230 Internal Server Error: /xadmin/users/user/
Traceback (most recent call last):
  File "C:\Users\Sunny_Future\AppData\Roaming\Python\Python36\site-packages\django\db\models\options.py", line 575, in get_field
    return self.fields_map[field_name]
KeyError: 'action_checkbox'

During handling of the above exception, another exception occurred:

Traceback (most recent call last):
  File "C:\Users\Sunny_Future\AppData\Roaming\Python\Python36\site-packages\xadmin\views\list.py", line 224, in get_list_queryset
    field = self.opts.get_field(field_name)
  File "C:\Users\Sunny_Future\AppData\Roaming\Python\Python36\site-packages\django\db\models\options.py", line 577, in get_field
    raise FieldDoesNotExist("%s has no field named '%s'" % (self.object_name, field_name))
django.core.exceptions.FieldDoesNotExist: User has no field named 'action_checkbox'

During handling of the above exception, another exception occurred:

Traceback (most recent call last):
  File "C:\Users\Sunny_Future\AppData\Roaming\Python\Python36\site-packages\django\core\handlers\exception.py", line 47, in inner
    response = get_response(request)
  File "C:\Users\Sunny_Future\AppData\Roaming\Python\Python36\site-packages\django\core\handlers\base.py", line 181, in _get_response
    response = wrapped_callback(request, *callback_args, **callback_kwargs)
  File "C:\Users\Sunny_Future\AppData\Roaming\Python\Python36\site-packages\xadmin\sites.py", line 300, in wrapper
    return self.admin_view(view, cacheable)(*args, **kwargs)
  File "C:\Users\Sunny_Future\AppData\Roaming\Python\Python36\site-packages\django\views\decorators\cache.py", line 44, in _wrapped_view_func
    response = view_func(request, *args, **kwargs)
  File "C:\Users\Sunny_Future\AppData\Roaming\Python\Python36\site-packages\xadmin\sites.py", line 208, in inner
    return view(request, *args, **kwargs)
  File "C:\Users\Sunny_Future\AppData\Roaming\Python\Python36\site-packages\xadmin\views\base.py", line 282, in view
    return handler(request, *args, **kwargs)
  File "C:\Users\Sunny_Future\AppData\Roaming\Python\Python36\site-packages\django\utils\decorators.py", line 43, in _wrapper
    return bound_method(*args, **kwargs)
  File "C:\Users\Sunny_Future\AppData\Roaming\Python\Python36\site-packages\django\utils\decorators.py", line 130, in _wrapped_view
    response = view_func(request, *args, **kwargs)
  File "C:\Users\Sunny_Future\AppData\Roaming\Python\Python36\site-packages\xadmin\views\base.py", line 80, in method
    return filter_chain(filters, len(filters) - 1, _inner_method, *args, **kwargs)
  File "C:\Users\Sunny_Future\AppData\Roaming\Python\Python36\site-packages\xadmin\views\base.py", line 49, in filter_chain
    return func()
  File "C:\Users\Sunny_Future\AppData\Roaming\Python\Python36\site-packages\xadmin\views\base.py", line 74, in _inner_method
    return func(self, *args, **kwargs)
  File "C:\Users\Sunny_Future\AppData\Roaming\Python\Python36\site-packages\xadmin\views\list.py", line 401, in get
    response = self.get_result_list()
  File "C:\Users\Sunny_Future\AppData\Roaming\Python\Python36\site-packages\xadmin\views\base.py", line 80, in method
    return filter_chain(filters, len(filters) - 1, _inner_method, *args, **kwargs)
  File "C:\Users\Sunny_Future\AppData\Roaming\Python\Python36\site-packages\xadmin\views\base.py", line 49, in filter_chain
    return func()
  File "C:\Users\Sunny_Future\AppData\Roaming\Python\Python36\site-packages\xadmin\views\base.py", line 74, in _inner_method
    return func(self, *args, **kwargs)
  File "C:\Users\Sunny_Future\AppData\Roaming\Python\Python36\site-packages\xadmin\views\list.py", line 200, in get_result_list
    return self.make_result_list()
  File "C:\Users\Sunny_Future\AppData\Roaming\Python\Python36\site-packages\xadmin\views\list.py", line 172, in make_result_list
    self.list_queryset = self.get_list_queryset()
  File "C:\Users\Sunny_Future\AppData\Roaming\Python\Python36\site-packages\xadmin\views\base.py", line 80, in method
    return filter_chain(filters, len(filters) - 1, _inner_method, *args, **kwargs)
  File "C:\Users\Sunny_Future\AppData\Roaming\Python\Python36\site-packages\xadmin\views\base.py", line 63, in filter_chain
    return filter_chain(filters, token - 1, _inner_method, *args, **kwargs)
  File "C:\Users\Sunny_Future\AppData\Roaming\Python\Python36\site-packages\xadmin\views\base.py", line 49, in filter_chain
    return func()
  File "C:\Users\Sunny_Future\AppData\Roaming\Python\Python36\site-packages\xadmin\views\base.py", line 62, in _inner_method
    return fm(func if fargs[1] == '__' else func(), *args, **kwargs)
  File "C:\Users\Sunny_Future\AppData\Roaming\Python\Python36\site-packages\xadmin\views\base.py", line 74, in _inner_method
    return func(self, *args, **kwargs)
  File "C:\Users\Sunny_Future\AppData\Roaming\Python\Python36\site-packages\xadmin\views\list.py", line 225, in get_list_queryset
    except models.FieldDoesNotExist:
AttributeError: module 'django.db.models' has no attribute 'FieldDoesNotExist'
ERROR 2021-01-27 22:41:28,452 basehttp 157 "GET /xadmin/users/user/ HTTP/1.1" 500 173778
INFO 2021-01-27 22:55:43,955 autoreload 240 C:\Users\Sunny_Future\AppData\Roaming\Python\Python36\site-packages\xadmin\plugins\relate.py changed, reloading.
INFO 2021-01-27 22:55:44,803 autoreload 617 Watching for file changes with StatReloader
INFO 2021-01-27 22:56:14,598 autoreload 617 Watching for file changes with StatReloader
INFO 2021-01-27 22:56:36,445 autoreload 240 C:\Users\Sunny_Future\AppData\Roaming\Python\Python36\site-packages\xadmin\models.py changed, reloading.
INFO 2021-01-27 22:56:37,354 autoreload 617 Watching for file changes with StatReloader
INFO 2021-01-27 22:57:13,646 autoreload 240 C:\Users\Sunny_Future\AppData\Roaming\Python\Python36\site-packages\xadmin\models.py changed, reloading.
INFO 2021-01-27 22:57:14,403 autoreload 617 Watching for file changes with StatReloader
INFO 2021-01-27 22:57:16,059 autoreload 617 Watching for file changes with StatReloader
INFO 2021-01-27 23:24:41,558 autoreload 617 Watching for file changes with StatReloader
INFO 2021-01-27 23:25:07,853 autoreload 617 Watching for file changes with StatReloader
INFO 2021-01-27 23:25:32,262 autoreload 617 Watching for file changes with StatReloader
INFO 2021-01-27 23:26:20,487 autoreload 617 Watching for file changes with StatReloader
INFO 2021-01-27 23:26:55,142 autoreload 617 Watching for file changes with StatReloader
INFO 2021-01-27 23:27:08,161 autoreload 240 C:\Users\Sunny_Future\AppData\Roaming\Python\Python36\site-packages\xadmin\plugins\importexport.py changed, reloading.
INFO 2021-01-27 23:27:10,978 autoreload 617 Watching for file changes with StatReloader
INFO 2021-01-27 23:28:13,843 autoreload 240 C:\Users\Sunny_Future\AppData\Roaming\Python\Python36\site-packages\xadmin\plugins\importexport.py changed, reloading.
INFO 2021-01-27 23:28:16,331 autoreload 617 Watching for file changes with StatReloader
INFO 2021-01-27 23:28:23,130 autoreload 240 C:\Users\Sunny_Future\AppData\Roaming\Python\Python36\site-packages\xadmin\plugins\importexport.py changed, reloading.
INFO 2021-01-27 23:28:25,980 autoreload 617 Watching for file changes with StatReloader
INFO 2021-01-27 23:29:11,079 autoreload 240 C:\Users\Sunny_Future\AppData\Roaming\Python\Python36\site-packages\xadmin\plugins\importexport.py changed, reloading.
INFO 2021-01-27 23:29:14,660 autoreload 617 Watching for file changes with StatReloader
INFO 2021-01-27 23:29:24,668 autoreload 240 C:\Users\Sunny_Future\AppData\Roaming\Python\Python36\site-packages\xadmin\plugins\importexport.py changed, reloading.
INFO 2021-01-27 23:29:27,942 autoreload 617 Watching for file changes with StatReloader
INFO 2021-01-27 23:29:48,277 autoreload 617 Watching for file changes with StatReloader
ERROR 2021-01-27 23:29:55,293 log 230 Internal Server Error: /xadmin/users/user/
Traceback (most recent call last):
  File "C:\Users\Sunny_Future\AppData\Roaming\Python\Python36\site-packages\django\db\models\options.py", line 575, in get_field
    return self.fields_map[field_name]
KeyError: 'action_checkbox'

During handling of the above exception, another exception occurred:

Traceback (most recent call last):
  File "C:\Users\Sunny_Future\AppData\Roaming\Python\Python36\site-packages\xadmin\views\list.py", line 224, in get_list_queryset
    field = self.opts.get_field(field_name)
  File "C:\Users\Sunny_Future\AppData\Roaming\Python\Python36\site-packages\django\db\models\options.py", line 577, in get_field
    raise FieldDoesNotExist("%s has no field named '%s'" % (self.object_name, field_name))
django.core.exceptions.FieldDoesNotExist: User has no field named 'action_checkbox'

During handling of the above exception, another exception occurred:

Traceback (most recent call last):
  File "C:\Users\Sunny_Future\AppData\Roaming\Python\Python36\site-packages\django\core\handlers\exception.py", line 47, in inner
    response = get_response(request)
  File "C:\Users\Sunny_Future\AppData\Roaming\Python\Python36\site-packages\django\core\handlers\base.py", line 181, in _get_response
    response = wrapped_callback(request, *callback_args, **callback_kwargs)
  File "C:\Users\Sunny_Future\AppData\Roaming\Python\Python36\site-packages\xadmin\sites.py", line 300, in wrapper
    return self.admin_view(view, cacheable)(*args, **kwargs)
  File "C:\Users\Sunny_Future\AppData\Roaming\Python\Python36\site-packages\django\views\decorators\cache.py", line 44, in _wrapped_view_func
    response = view_func(request, *args, **kwargs)
  File "C:\Users\Sunny_Future\AppData\Roaming\Python\Python36\site-packages\xadmin\sites.py", line 208, in inner
    return view(request, *args, **kwargs)
  File "C:\Users\Sunny_Future\AppData\Roaming\Python\Python36\site-packages\xadmin\views\base.py", line 282, in view
    return handler(request, *args, **kwargs)
  File "C:\Users\Sunny_Future\AppData\Roaming\Python\Python36\site-packages\django\utils\decorators.py", line 43, in _wrapper
    return bound_method(*args, **kwargs)
  File "C:\Users\Sunny_Future\AppData\Roaming\Python\Python36\site-packages\django\utils\decorators.py", line 130, in _wrapped_view
    response = view_func(request, *args, **kwargs)
  File "C:\Users\Sunny_Future\AppData\Roaming\Python\Python36\site-packages\xadmin\views\base.py", line 80, in method
    return filter_chain(filters, len(filters) - 1, _inner_method, *args, **kwargs)
  File "C:\Users\Sunny_Future\AppData\Roaming\Python\Python36\site-packages\xadmin\views\base.py", line 49, in filter_chain
    return func()
  File "C:\Users\Sunny_Future\AppData\Roaming\Python\Python36\site-packages\xadmin\views\base.py", line 74, in _inner_method
    return func(self, *args, **kwargs)
  File "C:\Users\Sunny_Future\AppData\Roaming\Python\Python36\site-packages\xadmin\views\list.py", line 401, in get
    response = self.get_result_list()
  File "C:\Users\Sunny_Future\AppData\Roaming\Python\Python36\site-packages\xadmin\views\base.py", line 80, in method
    return filter_chain(filters, len(filters) - 1, _inner_method, *args, **kwargs)
  File "C:\Users\Sunny_Future\AppData\Roaming\Python\Python36\site-packages\xadmin\views\base.py", line 49, in filter_chain
    return func()
  File "C:\Users\Sunny_Future\AppData\Roaming\Python\Python36\site-packages\xadmin\views\base.py", line 74, in _inner_method
    return func(self, *args, **kwargs)
  File "C:\Users\Sunny_Future\AppData\Roaming\Python\Python36\site-packages\xadmin\views\list.py", line 200, in get_result_list
    return self.make_result_list()
  File "C:\Users\Sunny_Future\AppData\Roaming\Python\Python36\site-packages\xadmin\views\list.py", line 172, in make_result_list
    self.list_queryset = self.get_list_queryset()
  File "C:\Users\Sunny_Future\AppData\Roaming\Python\Python36\site-packages\xadmin\views\base.py", line 80, in method
    return filter_chain(filters, len(filters) - 1, _inner_method, *args, **kwargs)
  File "C:\Users\Sunny_Future\AppData\Roaming\Python\Python36\site-packages\xadmin\views\base.py", line 63, in filter_chain
    return filter_chain(filters, token - 1, _inner_method, *args, **kwargs)
  File "C:\Users\Sunny_Future\AppData\Roaming\Python\Python36\site-packages\xadmin\views\base.py", line 49, in filter_chain
    return func()
  File "C:\Users\Sunny_Future\AppData\Roaming\Python\Python36\site-packages\xadmin\views\base.py", line 62, in _inner_method
    return fm(func if fargs[1] == '__' else func(), *args, **kwargs)
  File "C:\Users\Sunny_Future\AppData\Roaming\Python\Python36\site-packages\xadmin\views\base.py", line 74, in _inner_method
    return func(self, *args, **kwargs)
  File "C:\Users\Sunny_Future\AppData\Roaming\Python\Python36\site-packages\xadmin\views\list.py", line 225, in get_list_queryset
    except models.FieldDoesNotExist:
AttributeError: module 'django.db.models' has no attribute 'FieldDoesNotExist'
ERROR 2021-01-27 23:29:55,324 basehttp 157 "GET /xadmin/users/user/ HTTP/1.1" 500 173760
INFO 2021-01-27 23:30:16,822 basehttp 157 "GET /xadmin/ HTTP/1.1" 200 13710
INFO 2021-01-27 23:30:17,052 basehttp 157 "GET /xadmin/jsi18n/ HTTP/1.1" 200 7732
INFO 2021-01-27 23:31:41,292 autoreload 617 Watching for file changes with StatReloader
INFO 2021-01-27 23:31:48,121 basehttp 157 "GET /xadmin/ HTTP/1.1" 200 13710
INFO 2021-01-27 23:31:48,304 basehttp 157 "GET /xadmin/jsi18n/ HTTP/1.1" 200 7732
ERROR 2021-01-27 23:31:50,968 log 230 Internal Server Error: /xadmin/users/user/
Traceback (most recent call last):
  File "C:\Users\Sunny_Future\AppData\Roaming\Python\Python36\site-packages\django\db\models\options.py", line 575, in get_field
    return self.fields_map[field_name]
KeyError: 'action_checkbox'

During handling of the above exception, another exception occurred:

Traceback (most recent call last):
  File "C:\Users\Sunny_Future\AppData\Roaming\Python\Python36\site-packages\xadmin\views\list.py", line 264, in get_ordering_field
    field = self.opts.get_field(field_name)
  File "C:\Users\Sunny_Future\AppData\Roaming\Python\Python36\site-packages\django\db\models\options.py", line 577, in get_field
    raise FieldDoesNotExist("%s has no field named '%s'" % (self.object_name, field_name))
django.core.exceptions.FieldDoesNotExist: User has no field named 'action_checkbox'

During handling of the above exception, another exception occurred:

Traceback (most recent call last):
  File "C:\Users\Sunny_Future\AppData\Roaming\Python\Python36\site-packages\django\core\handlers\exception.py", line 47, in inner
    response = get_response(request)
  File "C:\Users\Sunny_Future\AppData\Roaming\Python\Python36\site-packages\django\core\handlers\base.py", line 181, in _get_response
    response = wrapped_callback(request, *callback_args, **callback_kwargs)
  File "C:\Users\Sunny_Future\AppData\Roaming\Python\Python36\site-packages\xadmin\sites.py", line 300, in wrapper
    return self.admin_view(view, cacheable)(*args, **kwargs)
  File "C:\Users\Sunny_Future\AppData\Roaming\Python\Python36\site-packages\django\views\decorators\cache.py", line 44, in _wrapped_view_func
    response = view_func(request, *args, **kwargs)
  File "C:\Users\Sunny_Future\AppData\Roaming\Python\Python36\site-packages\xadmin\sites.py", line 208, in inner
    return view(request, *args, **kwargs)
  File "C:\Users\Sunny_Future\AppData\Roaming\Python\Python36\site-packages\xadmin\views\base.py", line 282, in view
    return handler(request, *args, **kwargs)
  File "C:\Users\Sunny_Future\AppData\Roaming\Python\Python36\site-packages\django\utils\decorators.py", line 43, in _wrapper
    return bound_method(*args, **kwargs)
  File "C:\Users\Sunny_Future\AppData\Roaming\Python\Python36\site-packages\django\utils\decorators.py", line 130, in _wrapped_view
    response = view_func(request, *args, **kwargs)
  File "C:\Users\Sunny_Future\AppData\Roaming\Python\Python36\site-packages\xadmin\views\base.py", line 80, in method
    return filter_chain(filters, len(filters) - 1, _inner_method, *args, **kwargs)
  File "C:\Users\Sunny_Future\AppData\Roaming\Python\Python36\site-packages\xadmin\views\base.py", line 49, in filter_chain
    return func()
  File "C:\Users\Sunny_Future\AppData\Roaming\Python\Python36\site-packages\xadmin\views\base.py", line 74, in _inner_method
    return func(self, *args, **kwargs)
  File "C:\Users\Sunny_Future\AppData\Roaming\Python\Python36\site-packages\xadmin\views\list.py", line 405, in get
    response = self.get_result_list()
  File "C:\Users\Sunny_Future\AppData\Roaming\Python\Python36\site-packages\xadmin\views\base.py", line 80, in method
    return filter_chain(filters, len(filters) - 1, _inner_method, *args, **kwargs)
  File "C:\Users\Sunny_Future\AppData\Roaming\Python\Python36\site-packages\xadmin\views\base.py", line 49, in filter_chain
    return func()
  File "C:\Users\Sunny_Future\AppData\Roaming\Python\Python36\site-packages\xadmin\views\base.py", line 74, in _inner_method
    return func(self, *args, **kwargs)
  File "C:\Users\Sunny_Future\AppData\Roaming\Python\Python36\site-packages\xadmin\views\list.py", line 203, in get_result_list
    return self.make_result_list()
  File "C:\Users\Sunny_Future\AppData\Roaming\Python\Python36\site-packages\xadmin\views\list.py", line 176, in make_result_list
    self.ordering_field_columns = self.get_ordering_field_columns()
  File "C:\Users\Sunny_Future\AppData\Roaming\Python\Python36\site-packages\xadmin\views\base.py", line 80, in method
    return filter_chain(filters, len(filters) - 1, _inner_method, *args, **kwargs)
  File "C:\Users\Sunny_Future\AppData\Roaming\Python\Python36\site-packages\xadmin\views\base.py", line 49, in filter_chain
    return func()
  File "C:\Users\Sunny_Future\AppData\Roaming\Python\Python36\site-packages\xadmin\views\base.py", line 74, in _inner_method
    return func(self, *args, **kwargs)
  File "C:\Users\Sunny_Future\AppData\Roaming\Python\Python36\site-packages\xadmin\views\list.py", line 332, in get_ordering_field_columns
    if self.get_ordering_field(attr) == field:
  File "C:\Users\Sunny_Future\AppData\Roaming\Python\Python36\site-packages\xadmin\views\base.py", line 80, in method
    return filter_chain(filters, len(filters) - 1, _inner_method, *args, **kwargs)
  File "C:\Users\Sunny_Future\AppData\Roaming\Python\Python36\site-packages\xadmin\views\base.py", line 49, in filter_chain
    return func()
  File "C:\Users\Sunny_Future\AppData\Roaming\Python\Python36\site-packages\xadmin\views\base.py", line 74, in _inner_method
    return func(self, *args, **kwargs)
  File "C:\Users\Sunny_Future\AppData\Roaming\Python\Python36\site-packages\xadmin\views\list.py", line 266, in get_ordering_field
    except models.FieldDoesNotExist:
AttributeError: module 'django.db.models' has no attribute 'FieldDoesNotExist'
ERROR 2021-01-27 23:31:50,976 basehttp 157 "GET /xadmin/users/user/ HTTP/1.1" 500 181696
INFO 2021-01-27 23:32:19,378 autoreload 617 Watching for file changes with StatReloader
INFO 2021-01-27 23:32:25,328 basehttp 157 "GET /xadmin/users/user/ HTTP/1.1" 200 31650
INFO 2021-01-27 23:32:25,459 basehttp 157 "GET /static/xadmin/css/xadmin.form.css HTTP/1.1" 200 3763
INFO 2021-01-27 23:32:25,464 basehttp 157 "GET /static/xadmin/js/xadmin.plugin.details.js HTTP/1.1" 200 2319
INFO 2021-01-27 23:32:25,480 basehttp 157 "GET /static/xadmin/js/xadmin.plugin.bookmark.js HTTP/1.1" 200 529
INFO 2021-01-27 23:32:25,487 basehttp 157 "GET /static/xadmin/js/xadmin.plugin.filters.js HTTP/1.1" 200 1990
INFO 2021-01-27 23:32:25,491 basehttp 157 "GET /static/xadmin/js/xadmin.plugin.actions.js HTTP/1.1" 200 4198
INFO 2021-01-27 23:32:25,492 basehttp 157 "GET /static/xadmin/js/xadmin.page.list.js HTTP/1.1" 200 1105
INFO 2021-01-27 23:32:25,493 basehttp 157 "GET /static/xadmin/js/xadmin.page.form.js HTTP/1.1" 200 1948
INFO 2021-01-27 23:32:25,532 basehttp 157 "GET /xadmin/jsi18n/ HTTP/1.1" 200 7732
INFO 2021-01-27 23:32:39,843 basehttp 157 "GET /xadmin/users/user/add/ HTTP/1.1" 200 16933
INFO 2021-01-27 23:32:40,034 basehttp 157 "GET /xadmin/jsi18n/ HTTP/1.1" 200 7732
INFO 2021-01-27 23:32:54,614 basehttp 157 "POST /xadmin/users/user/add/ HTTP/1.1" 200 17504
INFO 2021-01-27 23:32:54,716 basehttp 157 "GET /xadmin/jsi18n/ HTTP/1.1" 200 7732
INFO 2021-01-27 23:33:10,532 basehttp 157 "POST /xadmin/users/user/add/ HTTP/1.1" 302 0
INFO 2021-01-27 23:33:10,824 basehttp 157 "GET /xadmin/users/user/ HTTP/1.1" 200 32772
INFO 2021-01-27 23:33:10,913 basehttp 157 "GET /xadmin/jsi18n/ HTTP/1.1" 200 7732
INFO 2021-01-27 23:33:17,085 basehttp 157 "GET /xadmin/users/user/2/update/ HTTP/1.1" 200 28015
INFO 2021-01-27 23:33:17,139 basehttp 157 "GET /static/xadmin/vendor/bootstrap-datepicker/css/datepicker.css HTTP/1.1" 200 10225
INFO 2021-01-27 23:33:17,148 basehttp 157 "GET /static/xadmin/vendor/bootstrap-clockpicker/bootstrap-clockpicker.css HTTP/1.1" 200 3729
INFO 2021-01-27 23:33:17,152 basehttp 157 "GET /static/xadmin/css/xadmin.widget.select-transfer.css HTTP/1.1" 200 2317
INFO 2021-01-27 23:33:17,156 basehttp 157 "GET /static/xadmin/js/xadmin.plugin.quick-form.js HTTP/1.1" 200 7546
INFO 2021-01-27 23:33:17,157 basehttp 157 "GET /static/xadmin/js/xadmin.widget.select-transfer.js HTTP/1.1" 200 8214
INFO 2021-01-27 23:33:17,157 basehttp 157 "GET /static/xadmin/vendor/bootstrap-clockpicker/bootstrap-clockpicker.js HTTP/1.1" 200 21112
INFO 2021-01-27 23:33:17,160 basehttp 157 "GET /static/xadmin/vendor/bootstrap-datepicker/js/bootstrap-datepicker.js HTTP/1.1" 200 32656
INFO 2021-01-27 23:33:17,197 basehttp 157 "GET /static/xadmin/js/xadmin.widget.datetime.js HTTP/1.1" 200 2979
INFO 2021-01-27 23:33:17,225 basehttp 157 "GET /xadmin/jsi18n/ HTTP/1.1" 200 7732
INFO 2021-01-27 23:33:23,430 basehttp 157 "GET /xadmin/users/user/2/delete/ HTTP/1.1" 200 14082
INFO 2021-01-27 23:33:23,615 basehttp 157 "GET /xadmin/jsi18n/ HTTP/1.1" 200 7732
INFO 2021-01-27 23:33:25,408 basehttp 157 "POST /xadmin/users/user/2/delete/ HTTP/1.1" 302 0
INFO 2021-01-27 23:33:25,733 basehttp 157 "GET /xadmin/users/user/ HTTP/1.1" 200 31880
INFO 2021-01-27 23:33:25,897 basehttp 157 "GET /xadmin/jsi18n/ HTTP/1.1" 200 7732
INFO 2021-01-27 23:44:20,407 basehttp 157 "GET /xadmin/users/user/?_cols=id.username.email.first_name.last_name.is_staff HTTP/1.1" 200 35069
INFO 2021-01-27 23:44:20,500 basehttp 157 "GET /static/xadmin/css/xadmin.form.css HTTP/1.1" 304 0
INFO 2021-01-27 23:44:20,513 basehttp 157 "GET /static/xadmin/js/xadmin.plugin.details.js HTTP/1.1" 304 0
INFO 2021-01-27 23:44:20,514 basehttp 157 "GET /static/xadmin/js/xadmin.plugin.filters.js HTTP/1.1" 304 0
INFO 2021-01-27 23:44:20,515 basehttp 157 "GET /static/xadmin/js/xadmin.plugin.bookmark.js HTTP/1.1" 304 0
INFO 2021-01-27 23:44:20,518 basehttp 157 "GET /static/xadmin/js/xadmin.page.list.js HTTP/1.1" 304 0
INFO 2021-01-27 23:44:20,520 basehttp 157 "GET /static/xadmin/js/xadmin.plugin.actions.js HTTP/1.1" 304 0
INFO 2021-01-27 23:44:20,525 basehttp 157 "GET /static/xadmin/js/xadmin.page.form.js HTTP/1.1" 304 0
INFO 2021-01-27 23:44:20,551 basehttp 157 "GET /xadmin/jsi18n/ HTTP/1.1" 200 7732
INFO 2021-01-27 23:44:43,886 basehttp 157 "GET /xadmin/xadmin/log/ HTTP/1.1" 200 35083
INFO 2021-01-27 23:44:44,043 basehttp 157 "GET /static/xadmin/vendor/select2/select2.css HTTP/1.1" 200 19226
INFO 2021-01-27 23:44:44,055 basehttp 157 "GET /static/xadmin/vendor/selectize/selectize.css HTTP/1.1" 200 8425
INFO 2021-01-27 23:44:44,056 basehttp 157 "GET /static/xadmin/vendor/bootstrap-datepicker/css/datepicker.css HTTP/1.1" 304 0
INFO 2021-01-27 23:44:44,067 basehttp 157 "GET /static/xadmin/vendor/selectize/selectize.bootstrap3.css HTTP/1.1" 200 10602
INFO 2021-01-27 23:44:44,075 basehttp 157 "GET /static/xadmin/vendor/select2/select2_locale_zh-Hans.js HTTP/1.1" 200 694
INFO 2021-01-27 23:44:44,079 basehttp 157 "GET /static/xadmin/js/xadmin.widget.select.js HTTP/1.1" 200 1344
INFO 2021-01-27 23:44:44,083 basehttp 157 "GET /static/xadmin/vendor/selectize/selectize.js HTTP/1.1" 200 98602
INFO 2021-01-27 23:44:44,088 basehttp 157 "GET /static/xadmin/vendor/select2/select2.js HTTP/1.1" 200 104906
INFO 2021-01-27 23:44:44,133 basehttp 157 "GET /static/xadmin/vendor/bootstrap-datepicker/js/bootstrap-datepicker.js HTTP/1.1" 304 0
INFO 2021-01-27 23:44:44,137 basehttp 157 "GET /static/xadmin/js/xadmin.widget.datetime.js HTTP/1.1" 304 0
INFO 2021-01-27 23:44:44,178 basehttp 157 "GET /xadmin/jsi18n/ HTTP/1.1" 200 7732
INFO 2021-01-27 23:44:49,647 basehttp 157 "GET /xadmin/users/user/ HTTP/1.1" 200 31650
INFO 2021-01-27 23:44:49,816 basehttp 157 "GET /xadmin/jsi18n/ HTTP/1.1" 200 7732
INFO 2021-01-27 23:44:51,703 basehttp 157 "GET /xadmin/auth/group/ HTTP/1.1" 200 22847
INFO 2021-01-27 23:44:51,878 basehttp 157 "GET /xadmin/jsi18n/ HTTP/1.1" 200 7732
INFO 2021-01-27 23:44:53,275 basehttp 157 "GET /xadmin/auth/permission/ HTTP/1.1" 200 46797
INFO 2021-01-27 23:44:53,389 basehttp 157 "GET /xadmin/jsi18n/ HTTP/1.1" 200 7732
INFO 2021-01-27 23:44:59,092 basehttp 157 "GET /xadmin/auth/group/ HTTP/1.1" 200 22847
INFO 2021-01-27 23:44:59,144 basehttp 157 "GET /xadmin/jsi18n/ HTTP/1.1" 200 7732
INFO 2021-01-27 23:45:02,510 basehttp 157 "GET /xadmin/reversion/revision/ HTTP/1.1" 200 28064
INFO 2021-01-27 23:45:02,687 basehttp 157 "GET /xadmin/jsi18n/ HTTP/1.1" 200 7732
INFO 2021-01-27 23:45:04,155 basehttp 157 "GET /xadmin/reversion/revision/ HTTP/1.1" 200 28064
INFO 2021-01-27 23:45:04,230 basehttp 157 "GET /xadmin/jsi18n/ HTTP/1.1" 200 7732
INFO 2021-01-27 23:45:05,291 basehttp 157 "GET /xadmin/users/user/ HTTP/1.1" 200 31650
INFO 2021-01-27 23:45:05,439 basehttp 157 "GET /xadmin/jsi18n/ HTTP/1.1" 200 7732
INFO 2021-01-27 23:47:28,803 autoreload 617 Watching for file changes with StatReloader
ERROR 2021-01-27 23:47:48,311 log 230 Internal Server Error: /xadmin/users/user/
Traceback (most recent call last):
  File "C:\Users\Sunny_Future\AppData\Roaming\Python\Python36\site-packages\django\db\models\options.py", line 575, in get_field
    return self.fields_map[field_name]
KeyError: 'action_checkbox'

During handling of the above exception, another exception occurred:

Traceback (most recent call last):
  File "C:\Users\Sunny_Future\AppData\Roaming\Python\Python36\site-packages\xadmin\views\list.py", line 264, in get_ordering_field
    field = self.opts.get_field(field_name)
  File "C:\Users\Sunny_Future\AppData\Roaming\Python\Python36\site-packages\django\db\models\options.py", line 577, in get_field
    raise FieldDoesNotExist("%s has no field named '%s'" % (self.object_name, field_name))
django.core.exceptions.FieldDoesNotExist: User has no field named 'action_checkbox'

During handling of the above exception, another exception occurred:

Traceback (most recent call last):
  File "C:\Users\Sunny_Future\AppData\Roaming\Python\Python36\site-packages\django\core\handlers\exception.py", line 47, in inner
    response = get_response(request)
  File "C:\Users\Sunny_Future\AppData\Roaming\Python\Python36\site-packages\django\core\handlers\base.py", line 181, in _get_response
    response = wrapped_callback(request, *callback_args, **callback_kwargs)
  File "C:\Users\Sunny_Future\AppData\Roaming\Python\Python36\site-packages\xadmin\sites.py", line 300, in wrapper
    return self.admin_view(view, cacheable)(*args, **kwargs)
  File "C:\Users\Sunny_Future\AppData\Roaming\Python\Python36\site-packages\django\views\decorators\cache.py", line 44, in _wrapped_view_func
    response = view_func(request, *args, **kwargs)
  File "C:\Users\Sunny_Future\AppData\Roaming\Python\Python36\site-packages\xadmin\sites.py", line 208, in inner
    return view(request, *args, **kwargs)
  File "C:\Users\Sunny_Future\AppData\Roaming\Python\Python36\site-packages\xadmin\views\base.py", line 282, in view
    return handler(request, *args, **kwargs)
  File "C:\Users\Sunny_Future\AppData\Roaming\Python\Python36\site-packages\django\utils\decorators.py", line 43, in _wrapper
    return bound_method(*args, **kwargs)
  File "C:\Users\Sunny_Future\AppData\Roaming\Python\Python36\site-packages\django\utils\decorators.py", line 130, in _wrapped_view
    response = view_func(request, *args, **kwargs)
  File "C:\Users\Sunny_Future\AppData\Roaming\Python\Python36\site-packages\xadmin\views\base.py", line 80, in method
    return filter_chain(filters, len(filters) - 1, _inner_method, *args, **kwargs)
  File "C:\Users\Sunny_Future\AppData\Roaming\Python\Python36\site-packages\xadmin\views\base.py", line 49, in filter_chain
    return func()
  File "C:\Users\Sunny_Future\AppData\Roaming\Python\Python36\site-packages\xadmin\views\base.py", line 74, in _inner_method
    return func(self, *args, **kwargs)
  File "C:\Users\Sunny_Future\AppData\Roaming\Python\Python36\site-packages\xadmin\views\list.py", line 406, in get
    response = self.get_result_list()
  File "C:\Users\Sunny_Future\AppData\Roaming\Python\Python36\site-packages\xadmin\views\base.py", line 80, in method
    return filter_chain(filters, len(filters) - 1, _inner_method, *args, **kwargs)
  File "C:\Users\Sunny_Future\AppData\Roaming\Python\Python36\site-packages\xadmin\views\base.py", line 49, in filter_chain
    return func()
  File "C:\Users\Sunny_Future\AppData\Roaming\Python\Python36\site-packages\xadmin\views\base.py", line 74, in _inner_method
    return func(self, *args, **kwargs)
  File "C:\Users\Sunny_Future\AppData\Roaming\Python\Python36\site-packages\xadmin\views\list.py", line 203, in get_result_list
    return self.make_result_list()
  File "C:\Users\Sunny_Future\AppData\Roaming\Python\Python36\site-packages\xadmin\views\list.py", line 176, in make_result_list
    self.ordering_field_columns = self.get_ordering_field_columns()
  File "C:\Users\Sunny_Future\AppData\Roaming\Python\Python36\site-packages\xadmin\views\base.py", line 80, in method
    return filter_chain(filters, len(filters) - 1, _inner_method, *args, **kwargs)
  File "C:\Users\Sunny_Future\AppData\Roaming\Python\Python36\site-packages\xadmin\views\base.py", line 49, in filter_chain
    return func()
  File "C:\Users\Sunny_Future\AppData\Roaming\Python\Python36\site-packages\xadmin\views\base.py", line 74, in _inner_method
    return func(self, *args, **kwargs)
  File "C:\Users\Sunny_Future\AppData\Roaming\Python\Python36\site-packages\xadmin\views\list.py", line 333, in get_ordering_field_columns
    if self.get_ordering_field(attr) == field:
  File "C:\Users\Sunny_Future\AppData\Roaming\Python\Python36\site-packages\xadmin\views\base.py", line 80, in method
    return filter_chain(filters, len(filters) - 1, _inner_method, *args, **kwargs)
  File "C:\Users\Sunny_Future\AppData\Roaming\Python\Python36\site-packages\xadmin\views\base.py", line 49, in filter_chain
    return func()
  File "C:\Users\Sunny_Future\AppData\Roaming\Python\Python36\site-packages\xadmin\views\base.py", line 74, in _inner_method
    return func(self, *args, **kwargs)
  File "C:\Users\Sunny_Future\AppData\Roaming\Python\Python36\site-packages\xadmin\views\list.py", line 266, in get_ordering_field
    except models.FieldDoesNotExist:
AttributeError: module 'django.db.models' has no attribute 'FieldDoesNotExist'
ERROR 2021-01-27 23:47:48,315 basehttp 157 "GET /xadmin/users/user/ HTTP/1.1" 500 181667
INFO 2021-01-27 23:49:51,994 autoreload 240 C:\Users\Sunny_Future\AppData\Roaming\Python\Python36\site-packages\xadmin\views\list.py changed, reloading.
INFO 2021-01-27 23:49:54,779 autoreload 617 Watching for file changes with StatReloader
INFO 2021-01-28 21:54:05,369 basehttp 157 "GET /xadmin/users/user/ HTTP/1.1" 200 31650
INFO 2021-01-28 21:54:05,500 basehttp 157 "GET /static/xadmin/vendor/bootstrap/css/bootstrap.css HTTP/1.1" 200 126432
INFO 2021-01-28 21:54:05,502 basehttp 157 "GET /static/xadmin/vendor/font-awesome/css/font-awesome.css HTTP/1.1" 200 21658
INFO 2021-01-28 21:54:05,519 basehttp 157 "GET /static/xadmin/css/xadmin.responsive.css HTTP/1.1" 200 4361
INFO 2021-01-28 21:54:05,561 basehttp 157 "GET /static/xadmin/css/xadmin.form.css HTTP/1.1" 304 0
INFO 2021-01-28 21:54:05,569 basehttp 157 "GET /static/xadmin/css/xadmin.main.css HTTP/1.1" 200 8376
INFO 2021-01-28 21:54:05,569 basehttp 157 "GET /static/xadmin/css/xadmin.plugins.css HTTP/1.1" 200 175
INFO 2021-01-28 21:54:05,585 basehttp 157 "GET /xadmin/jsi18n/ HTTP/1.1" 200 7732
INFO 2021-01-28 21:54:05,587 basehttp 157 "GET /static/xadmin/vendor/jquery-ui/jquery.ui.widget.js HTTP/1.1" 200 15069
INFO 2021-01-28 21:54:05,593 basehttp 157 "GET /static/xadmin/js/xadmin.main.js HTTP/1.1" 200 3401
INFO 2021-01-28 21:54:05,594 basehttp 157 "GET /static/xadmin/vendor/jquery/jquery.js HTTP/1.1" 200 240196
INFO 2021-01-28 21:54:05,601 basehttp 157 "GET /static/xadmin/vendor/jquery-ui/jquery.ui.mouse.js HTTP/1.1" 200 4561
INFO 2021-01-28 21:54:05,613 basehttp 157 "GET /static/xadmin/vendor/jquery-ui/jquery.ui.core.js HTTP/1.1" 200 8195
INFO 2021-01-28 21:54:05,619 basehttp 157 "GET /static/xadmin/js/xadmin.plugin.details.js HTTP/1.1" 304 0
INFO 2021-01-28 21:54:05,623 basehttp 157 "GET /static/xadmin/vendor/bootstrap/js/bootstrap.js HTTP/1.1" 200 58327
INFO 2021-01-28 21:54:05,627 basehttp 157 "GET /static/xadmin/vendor/jquery-ui/jquery.ui.sortable.js HTTP/1.1" 200 42543
INFO 2021-01-28 21:54:05,627 basehttp 157 "GET /static/xadmin/js/xadmin.plugin.bookmark.js HTTP/1.1" 304 0
INFO 2021-01-28 21:54:05,635 basehttp 157 "GET /static/xadmin/js/xadmin.plugin.actions.js HTTP/1.1" 304 0
INFO 2021-01-28 21:54:05,636 basehttp 157 "GET /static/xadmin/js/xadmin.plugin.filters.js HTTP/1.1" 304 0
INFO 2021-01-28 21:54:05,638 basehttp 157 "GET /static/xadmin/js/xadmin.page.list.js HTTP/1.1" 304 0
INFO 2021-01-28 21:54:05,645 basehttp 157 "GET /static/xadmin/js/xadmin.page.form.js HTTP/1.1" 304 0
INFO 2021-01-28 21:54:05,646 basehttp 157 "GET /static/xadmin/js/xadmin.responsive.js HTTP/1.1" 200 4165
INFO 2021-01-28 21:54:05,647 basehttp 157 "GET /static/xadmin/js/xadmin.plugin.themes.js HTTP/1.1" 200 3489
INFO 2021-01-28 21:54:05,655 basehttp 157 "GET /static/xadmin/vendor/jquery-ui/jquery.ui.effect.js HTTP/1.1" 200 31918
INFO 2021-01-28 21:54:08,587 basehttp 157 "GET /static/xadmin/vendor/font-awesome/fonts/fontawesome-webfont.woff?v=4.0.3 HTTP/1.1" 200 44432
INFO 2021-01-28 22:45:40,391 basehttp 157 "GET /xadmin/users/user/ HTTP/1.1" 200 31650
INFO 2021-01-28 22:45:40,590 basehttp 157 "GET /xadmin/jsi18n/ HTTP/1.1" 200 7732
INFO 2021-01-28 22:45:49,910 basehttp 157 "GET /xadmin/xadmin/log/ HTTP/1.1" 200 35083
INFO 2021-01-28 22:45:50,079 basehttp 157 "GET /static/xadmin/vendor/bootstrap-datepicker/css/datepicker.css HTTP/1.1" 304 0
INFO 2021-01-28 22:45:50,092 basehttp 157 "GET /static/xadmin/vendor/select2/select2.css HTTP/1.1" 304 0
INFO 2021-01-28 22:45:50,093 basehttp 157 "GET /static/xadmin/vendor/selectize/selectize.bootstrap3.css HTTP/1.1" 304 0
INFO 2021-01-28 22:45:50,094 basehttp 157 "GET /static/xadmin/vendor/selectize/selectize.css HTTP/1.1" 304 0
INFO 2021-01-28 22:45:50,098 basehttp 157 "GET /static/xadmin/vendor/selectize/selectize.js HTTP/1.1" 304 0
INFO 2021-01-28 22:45:50,098 basehttp 157 "GET /static/xadmin/js/xadmin.widget.datetime.js HTTP/1.1" 304 0
INFO 2021-01-28 22:45:50,107 basehttp 157 "GET /static/xadmin/vendor/select2/select2.js HTTP/1.1" 304 0
INFO 2021-01-28 22:45:50,109 basehttp 157 "GET /static/xadmin/vendor/select2/select2_locale_zh-Hans.js HTTP/1.1" 304 0
INFO 2021-01-28 22:45:50,110 basehttp 157 "GET /static/xadmin/vendor/bootstrap-datepicker/js/bootstrap-datepicker.js HTTP/1.1" 304 0
INFO 2021-01-28 22:45:50,112 basehttp 157 "GET /static/xadmin/js/xadmin.widget.select.js HTTP/1.1" 304 0
INFO 2021-01-28 22:45:50,137 basehttp 157 "GET /xadmin/jsi18n/ HTTP/1.1" 200 7732
INFO 2021-01-28 22:45:57,952 basehttp 157 "GET /xadmin/xadmin/log/ HTTP/1.1" 200 35083
INFO 2021-01-28 22:45:58,126 basehttp 157 "GET /xadmin/jsi18n/ HTTP/1.1" 200 7732
INFO 2021-01-28 22:46:00,724 basehttp 157 "GET /xadmin/xadmin/log/2/update/ HTTP/1.1" 200 19491
INFO 2021-01-28 22:46:00,846 basehttp 157 "GET /static/xadmin/js/xadmin.plugin.quick-form.js HTTP/1.1" 304 0
INFO 2021-01-28 22:46:00,886 basehttp 157 "GET /static/xadmin/js/xadmin.plugin.portal.js HTTP/1.1" 200 1000
INFO 2021-01-28 22:46:00,907 basehttp 157 "GET /xadmin/jsi18n/ HTTP/1.1" 200 7732
INFO 2021-01-28 22:46:09,920 basehttp 157 "GET /xadmin/xadmin/log/ HTTP/1.1" 200 35083
INFO 2021-01-28 22:46:10,090 basehttp 157 "GET /xadmin/jsi18n/ HTTP/1.1" 200 7732
ERROR 2021-01-28 22:46:20,696 log 230 Internal Server Error: /xadmin/xadmin/log/
Traceback (most recent call last):
  File "C:\Users\Sunny_Future\AppData\Roaming\Python\Python36\site-packages\django\core\handlers\exception.py", line 47, in inner
    response = get_response(request)
  File "C:\Users\Sunny_Future\AppData\Roaming\Python\Python36\site-packages\django\core\handlers\base.py", line 181, in _get_response
    response = wrapped_callback(request, *callback_args, **callback_kwargs)
  File "C:\Users\Sunny_Future\AppData\Roaming\Python\Python36\site-packages\xadmin\sites.py", line 300, in wrapper
    return self.admin_view(view, cacheable)(*args, **kwargs)
  File "C:\Users\Sunny_Future\AppData\Roaming\Python\Python36\site-packages\django\views\decorators\cache.py", line 44, in _wrapped_view_func
    response = view_func(request, *args, **kwargs)
  File "C:\Users\Sunny_Future\AppData\Roaming\Python\Python36\site-packages\xadmin\sites.py", line 208, in inner
    return view(request, *args, **kwargs)
  File "C:\Users\Sunny_Future\AppData\Roaming\Python\Python36\site-packages\xadmin\views\base.py", line 282, in view
    return handler(request, *args, **kwargs)
  File "C:\Users\Sunny_Future\AppData\Roaming\Python\Python36\site-packages\django\utils\decorators.py", line 43, in _wrapper
    return bound_method(*args, **kwargs)
  File "C:\Users\Sunny_Future\AppData\Roaming\Python\Python36\site-packages\django\utils\decorators.py", line 130, in _wrapped_view
    response = view_func(request, *args, **kwargs)
  File "C:\Users\Sunny_Future\AppData\Roaming\Python\Python36\site-packages\xadmin\views\base.py", line 80, in method
    return filter_chain(filters, len(filters) - 1, _inner_method, *args, **kwargs)
  File "C:\Users\Sunny_Future\AppData\Roaming\Python\Python36\site-packages\xadmin\views\base.py", line 49, in filter_chain
    return func()
  File "C:\Users\Sunny_Future\AppData\Roaming\Python\Python36\site-packages\xadmin\views\base.py", line 74, in _inner_method
    return func(self, *args, **kwargs)
  File "C:\Users\Sunny_Future\AppData\Roaming\Python\Python36\site-packages\xadmin\views\list.py", line 413, in get
    response = self.get_response(context, *args, **kwargs)
  File "C:\Users\Sunny_Future\AppData\Roaming\Python\Python36\site-packages\xadmin\views\base.py", line 80, in method
    return filter_chain(filters, len(filters) - 1, _inner_method, *args, **kwargs)
  File "C:\Users\Sunny_Future\AppData\Roaming\Python\Python36\site-packages\xadmin\views\base.py", line 63, in filter_chain
    return filter_chain(filters, token - 1, _inner_method, *args, **kwargs)
  File "C:\Users\Sunny_Future\AppData\Roaming\Python\Python36\site-packages\xadmin\views\base.py", line 49, in filter_chain
    return func()
  File "C:\Users\Sunny_Future\AppData\Roaming\Python\Python36\site-packages\xadmin\views\base.py", line 62, in _inner_method
    return fm(func if fargs[1] == '__' else func(), *args, **kwargs)
  File "C:\Users\Sunny_Future\AppData\Roaming\Python\Python36\site-packages\xadmin\plugins\export.py", line 230, in get_response
    response.write(getattr(self, 'get_%s_export' % file_type)(context))
  File "C:\Users\Sunny_Future\AppData\Roaming\Python\Python36\site-packages\xadmin\plugins\export.py", line 217, in get_json_export
    results = self._get_objects(context)
  File "C:\Users\Sunny_Future\AppData\Roaming\Python\Python36\site-packages\xadmin\plugins\export.py", line 81, in _get_objects
    enumerate(filter(lambda c:getattr(c, 'export', False), r.cells))]) for r in rows]
  File "C:\Users\Sunny_Future\AppData\Roaming\Python\Python36\site-packages\xadmin\plugins\export.py", line 81, in <listcomp>
    enumerate(filter(lambda c:getattr(c, 'export', False), r.cells))]) for r in rows]
  File "C:\Users\Sunny_Future\AppData\Roaming\Python\Python36\site-packages\xadmin\plugins\export.py", line 80, in <listcomp>
    (force_text(headers[i].text), self._format_value(o)) for i, o in
IndexError: list index out of range
ERROR 2021-01-28 22:46:20,707 basehttp 157 "GET /xadmin/xadmin/log/?_do_=export&export_type=json&export_json_format=on HTTP/1.1" 500 156002
INFO 2021-01-28 22:46:31,617 basehttp 157 "GET /xadmin/xadmin/log/ HTTP/1.1" 200 35083
INFO 2021-01-28 22:46:36,159 basehttp 157 "GET /xadmin/users/user/ HTTP/1.1" 200 31650
INFO 2021-01-28 22:46:36,221 basehttp 157 "GET /xadmin/jsi18n/ HTTP/1.1" 200 7732
INFO 2021-01-28 22:46:40,511 basehttp 157 "GET /xadmin/users/user/ HTTP/1.1" 200 31650
INFO 2021-01-28 22:46:40,666 basehttp 157 "GET /xadmin/jsi18n/ HTTP/1.1" 200 7732
INFO 2021-01-28 22:47:23,297 basehttp 157 "GET /xadmin/users/user/add/ HTTP/1.1" 200 16933
INFO 2021-01-28 22:47:23,476 basehttp 157 "GET /xadmin/jsi18n/ HTTP/1.1" 200 7732
INFO 2021-01-28 22:47:38,185 basehttp 157 "POST /xadmin/users/user/add/ HTTP/1.1" 200 17504
INFO 2021-01-28 22:47:38,354 basehttp 157 "GET /xadmin/jsi18n/ HTTP/1.1" 200 7732
INFO 2021-01-28 22:47:51,574 basehttp 157 "POST /xadmin/users/user/add/ HTTP/1.1" 200 17274
INFO 2021-01-28 22:47:51,648 basehttp 157 "GET /xadmin/jsi18n/ HTTP/1.1" 200 7732
INFO 2021-01-28 22:48:05,749 basehttp 157 "POST /xadmin/users/user/add/ HTTP/1.1" 302 0
INFO 2021-01-28 22:48:06,273 basehttp 157 "GET /xadmin/users/user/ HTTP/1.1" 200 32772
INFO 2021-01-28 22:48:06,457 basehttp 157 "GET /xadmin/jsi18n/ HTTP/1.1" 200 7732
INFO 2021-01-28 22:48:22,915 basehttp 157 "GET /xadmin/users/user/2/update/ HTTP/1.1" 200 28015
INFO 2021-01-28 22:48:23,049 basehttp 157 "GET /static/xadmin/vendor/bootstrap-clockpicker/bootstrap-clockpicker.css HTTP/1.1" 304 0
INFO 2021-01-28 22:48:23,052 basehttp 157 "GET /static/xadmin/css/xadmin.widget.select-transfer.css HTTP/1.1" 304 0
INFO 2021-01-28 22:48:23,061 basehttp 157 "GET /static/xadmin/js/xadmin.widget.select-transfer.js HTTP/1.1" 304 0
INFO 2021-01-28 22:48:23,063 basehttp 157 "GET /static/xadmin/vendor/bootstrap-clockpicker/bootstrap-clockpicker.js HTTP/1.1" 304 0
INFO 2021-01-28 22:48:23,113 basehttp 157 "GET /xadmin/jsi18n/ HTTP/1.1" 200 7732
INFO 2021-01-28 22:49:08,419 basehttp 157 "GET /xadmin/users/user/2/delete/ HTTP/1.1" 200 14082
INFO 2021-01-28 22:49:08,586 basehttp 157 "GET /xadmin/jsi18n/ HTTP/1.1" 200 7732
INFO 2021-01-28 22:49:10,484 basehttp 157 "POST /xadmin/users/user/2/delete/ HTTP/1.1" 302 0
INFO 2021-01-28 22:49:10,984 basehttp 157 "GET /xadmin/users/user/ HTTP/1.1" 200 31880
INFO 2021-01-28 22:49:11,173 basehttp 157 "GET /xadmin/jsi18n/ HTTP/1.1" 200 7732
INFO 2021-01-28 22:51:00,756 basehttp 157 "GET /xadmin/users/user/ HTTP/1.1" 200 31650
INFO 2021-01-28 22:51:00,951 basehttp 157 "GET /xadmin/jsi18n/ HTTP/1.1" 200 7732
INFO 2021-01-28 22:51:27,963 basehttp 157 "GET /xadmin/users/user/?_q_=admin HTTP/1.1" 200 33276
INFO 2021-01-28 22:51:28,170 basehttp 157 "GET /xadmin/jsi18n/ HTTP/1.1" 200 7732
INFO 2021-01-28 22:52:38,694 basehttp 157 "GET /xadmin/users/user/add/ HTTP/1.1" 200 16933
INFO 2021-01-28 22:52:38,889 basehttp 157 "GET /xadmin/jsi18n/ HTTP/1.1" 200 7732
INFO 2021-01-28 22:53:15,411 basehttp 157 "POST /xadmin/users/user/add/ HTTP/1.1" 302 0
INFO 2021-01-28 22:53:15,977 basehttp 157 "GET /xadmin/users/user/ HTTP/1.1" 200 32772
INFO 2021-01-28 22:53:16,140 basehttp 157 "GET /xadmin/jsi18n/ HTTP/1.1" 200 7732
INFO 2021-01-28 22:53:23,748 basehttp 157 "GET /xadmin/users/user/ HTTP/1.1" 200 32480
INFO 2021-01-28 22:53:27,205 basehttp 157 "GET /xadmin/ HTTP/1.1" 200 13710
INFO 2021-01-28 22:53:27,300 basehttp 157 "GET /static/xadmin/css/xadmin.page.dashboard.css HTTP/1.1" 200 790
INFO 2021-01-28 22:53:27,343 basehttp 157 "GET /static/xadmin/js/xadmin.page.dashboard.js HTTP/1.1" 200 3208
INFO 2021-01-28 22:53:27,374 basehttp 157 "GET /xadmin/jsi18n/ HTTP/1.1" 200 7732
INFO 2021-01-28 22:53:29,804 basehttp 157 "GET /xadmin/ HTTP/1.1" 200 13710
INFO 2021-01-28 22:53:33,157 basehttp 157 "GET /xadmin/logout/ HTTP/1.1" 200 2637
INFO 2021-01-28 22:53:33,358 basehttp 157 "GET /xadmin/jsi18n/ HTTP/1.1" 200 4136
INFO 2021-01-28 22:53:39,020 basehttp 157 "GET /xadmin/ HTTP/1.1" 200 4129
INFO 2021-01-28 22:53:39,140 basehttp 157 "GET /xadmin/jsi18n/ HTTP/1.1" 200 4136
INFO 2021-01-28 22:53:49,299 basehttp 157 "POST /xadmin/ HTTP/1.1" 200 4366
INFO 2021-01-28 22:53:49,372 basehttp 157 "GET /xadmin/jsi18n/ HTTP/1.1" 200 4136
INFO 2021-01-28 22:53:59,474 basehttp 157 "POST /xadmin/ HTTP/1.1" 200 4366
INFO 2021-01-28 22:53:59,580 basehttp 157 "GET /xadmin/jsi18n/ HTTP/1.1" 200 4136
INFO 2021-01-28 22:54:21,451 basehttp 157 "POST /xadmin/ HTTP/1.1" 200 4366
INFO 2021-01-28 22:54:21,577 basehttp 157 "GET /xadmin/jsi18n/ HTTP/1.1" 200 4136
INFO 2021-01-28 22:54:28,058 basehttp 157 "POST /xadmin/ HTTP/1.1" 302 0
INFO 2021-01-28 22:54:28,295 basehttp 157 "GET /xadmin/ HTTP/1.1" 200 13710
INFO 2021-01-28 22:54:28,445 basehttp 157 "GET /xadmin/jsi18n/ HTTP/1.1" 200 7732
INFO 2021-01-28 22:54:33,308 basehttp 157 "GET /xadmin/users/user/ HTTP/1.1" 200 32480
INFO 2021-01-28 22:54:33,466 basehttp 157 "GET /xadmin/jsi18n/ HTTP/1.1" 200 7732
INFO 2021-01-28 23:26:10,539 autoreload 617 Watching for file changes with StatReloader
INFO 2021-01-28 23:29:40,916 autoreload 240 C:\Users\Sunny_Future\AppData\Roaming\Python\Python36\site-packages\xadmin\plugins\aggregation.py changed, reloading.
INFO 2021-01-28 23:29:40,955 autoreload 240 C:\Users\Sunny_Future\AppData\Roaming\Python\Python36\site-packages\xadmin\plugins\aggregation.py changed, reloading.
INFO 2021-01-28 23:29:44,429 autoreload 617 Watching for file changes with StatReloader
INFO 2021-01-28 23:29:44,429 autoreload 617 Watching for file changes with StatReloader
INFO 2021-01-28 23:55:26,034 autoreload 240 F:\文档\code\pythonCode\hippo\hippo_api\hippo_api\settings\dev.py changed, reloading.
INFO 2021-01-28 23:55:28,184 autoreload 617 Watching for file changes with StatReloader
INFO 2021-01-28 23:55:28,825 autoreload 617 Watching for file changes with StatReloader
INFO 2021-01-28 23:55:48,341 basehttp 157 "GET /xadmin/users/user/ HTTP/1.1" 200 32480
INFO 2021-01-28 23:55:48,475 basehttp 157 "GET /xadmin/jsi18n/ HTTP/1.1" 200 7732
INFO 2021-01-28 23:55:52,077 basehttp 157 "GET /xadmin/xadmin/log/ HTTP/1.1" 200 38329
INFO 2021-01-28 23:55:52,224 basehttp 157 "GET /xadmin/jsi18n/ HTTP/1.1" 200 7732
INFO 2021-01-29 00:09:28,347 autoreload 240 F:\文档\code\pythonCode\hippo\hippo_api\hippo_api\settings\dev.py changed, reloading.
INFO 2021-01-29 00:09:28,351 autoreload 240 F:\文档\code\pythonCode\hippo\hippo_api\hippo_api\settings\dev.py changed, reloading.
INFO 2021-01-29 00:09:30,824 autoreload 617 Watching for file changes with StatReloader
INFO 2021-01-29 00:09:30,857 autoreload 617 Watching for file changes with StatReloader
INFO 2021-01-29 00:10:01,543 basehttp 157 "GET /xadmin/xadmin/log/ HTTP/1.1" 200 39455
INFO 2021-01-29 00:10:01,718 basehttp 157 "GET /xadmin/jsi18n/ HTTP/1.1" 200 7732
INFO 2021-01-29 00:10:07,035 basehttp 157 "GET /xadmin/host/hosts/ HTTP/1.1" 200 23746
INFO 2021-01-29 00:10:07,167 basehttp 157 "GET /xadmin/jsi18n/ HTTP/1.1" 200 7732
INFO 2021-01-29 00:10:13,793 basehttp 157 "GET /xadmin/host/hosts/ HTTP/1.1" 200 23746
INFO 2021-01-29 00:10:13,918 basehttp 157 "GET /xadmin/jsi18n/ HTTP/1.1" 200 7732
INFO 2021-01-29 00:10:18,823 basehttp 157 "GET /xadmin/host/hosts/add/ HTTP/1.1" 200 17004
INFO 2021-01-29 00:10:19,019 basehttp 157 "GET /xadmin/jsi18n/ HTTP/1.1" 200 7732
INFO 2021-01-29 00:10:21,743 basehttp 157 "GET /xadmin/host/hosts/ HTTP/1.1" 200 23746
ERROR 2021-01-30 16:19:05,214 log 230 Internal Server Error: /xadmin/host/hosts/
Traceback (most recent call last):
  File "C:\Users\Sunny_Future\AppData\Roaming\Python\Python36\site-packages\django\contrib\sessions\backends\base.py", line 233, in _get_session
    return self._session_cache
AttributeError: 'SessionStore' object has no attribute '_session_cache'

During handling of the above exception, another exception occurred:

Traceback (most recent call last):
  File "C:\Users\Sunny_Future\AppData\Roaming\Python\Python36\site-packages\pymysql\connections.py", line 614, in connect
    (self.host, self.port), self.connect_timeout, **kwargs
  File "D:\Program files\python36\lib\socket.py", line 724, in create_connection
    raise err
  File "D:\Program files\python36\lib\socket.py", line 713, in create_connection
    sock.connect(sa)
socket.timeout: timed out

During handling of the above exception, another exception occurred:

Traceback (most recent call last):
  File "C:\Users\Sunny_Future\AppData\Roaming\Python\Python36\site-packages\django\db\backends\base\base.py", line 219, in ensure_connection
    self.connect()
  File "C:\Users\Sunny_Future\AppData\Roaming\Python\Python36\site-packages\django\utils\asyncio.py", line 26, in inner
    return func(*args, **kwargs)
  File "C:\Users\Sunny_Future\AppData\Roaming\Python\Python36\site-packages\django\db\backends\base\base.py", line 200, in connect
    self.connection = self.get_new_connection(conn_params)
  File "C:\Users\Sunny_Future\AppData\Roaming\Python\Python36\site-packages\django\utils\asyncio.py", line 26, in inner
    return func(*args, **kwargs)
  File "C:\Users\Sunny_Future\AppData\Roaming\Python\Python36\site-packages\django\db\backends\mysql\base.py", line 234, in get_new_connection
    return Database.connect(**conn_params)
  File "C:\Users\Sunny_Future\AppData\Roaming\Python\Python36\site-packages\pymysql\connections.py", line 353, in __init__
    self.connect()
  File "C:\Users\Sunny_Future\AppData\Roaming\Python\Python36\site-packages\pymysql\connections.py", line 664, in connect
    raise exc
pymysql.err.OperationalError: (2003, "Can't connect to MySQL server on '192.168.137.11' (timed out)")

The above exception was the direct cause of the following exception:

Traceback (most recent call last):
  File "C:\Users\Sunny_Future\AppData\Roaming\Python\Python36\site-packages\django\core\handlers\exception.py", line 47, in inner
    response = get_response(request)
  File "C:\Users\Sunny_Future\AppData\Roaming\Python\Python36\site-packages\django\core\handlers\base.py", line 181, in _get_response
    response = wrapped_callback(request, *callback_args, **callback_kwargs)
  File "C:\Users\Sunny_Future\AppData\Roaming\Python\Python36\site-packages\xadmin\sites.py", line 300, in wrapper
    return self.admin_view(view, cacheable)(*args, **kwargs)
  File "C:\Users\Sunny_Future\AppData\Roaming\Python\Python36\site-packages\django\views\decorators\cache.py", line 44, in _wrapped_view_func
    response = view_func(request, *args, **kwargs)
  File "C:\Users\Sunny_Future\AppData\Roaming\Python\Python36\site-packages\xadmin\sites.py", line 206, in inner
    if not self.has_permission(request) and getattr(view, 'need_site_permission', True):
  File "C:\Users\Sunny_Future\AppData\Roaming\Python\Python36\site-packages\xadmin\sites.py", line 161, in has_permission
    return request.user.is_active and request.user.is_staff
  File "C:\Users\Sunny_Future\AppData\Roaming\Python\Python36\site-packages\django\utils\functional.py", line 240, in inner
    self._setup()
  File "C:\Users\Sunny_Future\AppData\Roaming\Python\Python36\site-packages\django\utils\functional.py", line 376, in _setup
    self._wrapped = self._setupfunc()
  File "C:\Users\Sunny_Future\AppData\Roaming\Python\Python36\site-packages\django\contrib\auth\middleware.py", line 23, in <lambda>
    request.user = SimpleLazyObject(lambda: get_user(request))
  File "C:\Users\Sunny_Future\AppData\Roaming\Python\Python36\site-packages\django\contrib\auth\middleware.py", line 11, in get_user
    request._cached_user = auth.get_user(request)
  File "C:\Users\Sunny_Future\AppData\Roaming\Python\Python36\site-packages\django\contrib\auth\__init__.py", line 174, in get_user
    user_id = _get_user_session_key(request)
  File "C:\Users\Sunny_Future\AppData\Roaming\Python\Python36\site-packages\django\contrib\auth\__init__.py", line 58, in _get_user_session_key
    return get_user_model()._meta.pk.to_python(request.session[SESSION_KEY])
  File "C:\Users\Sunny_Future\AppData\Roaming\Python\Python36\site-packages\django\contrib\sessions\backends\base.py", line 65, in __getitem__
    return self._session[key]
  File "C:\Users\Sunny_Future\AppData\Roaming\Python\Python36\site-packages\django\contrib\sessions\backends\base.py", line 238, in _get_session
    self._session_cache = self.load()
  File "C:\Users\Sunny_Future\AppData\Roaming\Python\Python36\site-packages\django\contrib\sessions\backends\db.py", line 43, in load
    s = self._get_session_from_db()
  File "C:\Users\Sunny_Future\AppData\Roaming\Python\Python36\site-packages\django\contrib\sessions\backends\db.py", line 34, in _get_session_from_db
    expire_date__gt=timezone.now()
  File "C:\Users\Sunny_Future\AppData\Roaming\Python\Python36\site-packages\django\db\models\manager.py", line 85, in manager_method
    return getattr(self.get_queryset(), name)(*args, **kwargs)
  File "C:\Users\Sunny_Future\AppData\Roaming\Python\Python36\site-packages\django\db\models\query.py", line 425, in get
    num = len(clone)
  File "C:\Users\Sunny_Future\AppData\Roaming\Python\Python36\site-packages\django\db\models\query.py", line 269, in __len__
    self._fetch_all()
  File "C:\Users\Sunny_Future\AppData\Roaming\Python\Python36\site-packages\django\db\models\query.py", line 1308, in _fetch_all
    self._result_cache = list(self._iterable_class(self))
  File "C:\Users\Sunny_Future\AppData\Roaming\Python\Python36\site-packages\django\db\models\query.py", line 53, in __iter__
    results = compiler.execute_sql(chunked_fetch=self.chunked_fetch, chunk_size=self.chunk_size)
  File "C:\Users\Sunny_Future\AppData\Roaming\Python\Python36\site-packages\django\db\models\sql\compiler.py", line 1154, in execute_sql
    cursor = self.connection.cursor()
  File "C:\Users\Sunny_Future\AppData\Roaming\Python\Python36\site-packages\django\utils\asyncio.py", line 26, in inner
    return func(*args, **kwargs)
  File "C:\Users\Sunny_Future\AppData\Roaming\Python\Python36\site-packages\django\db\backends\base\base.py", line 259, in cursor
    return self._cursor()
  File "C:\Users\Sunny_Future\AppData\Roaming\Python\Python36\site-packages\django\db\backends\base\base.py", line 235, in _cursor
    self.ensure_connection()
  File "C:\Users\Sunny_Future\AppData\Roaming\Python\Python36\site-packages\django\utils\asyncio.py", line 26, in inner
    return func(*args, **kwargs)
  File "C:\Users\Sunny_Future\AppData\Roaming\Python\Python36\site-packages\django\db\backends\base\base.py", line 219, in ensure_connection
    self.connect()
  File "C:\Users\Sunny_Future\AppData\Roaming\Python\Python36\site-packages\django\db\utils.py", line 90, in __exit__
    raise dj_exc_value.with_traceback(traceback) from exc_value
  File "C:\Users\Sunny_Future\AppData\Roaming\Python\Python36\site-packages\django\db\backends\base\base.py", line 219, in ensure_connection
    self.connect()
  File "C:\Users\Sunny_Future\AppData\Roaming\Python\Python36\site-packages\django\utils\asyncio.py", line 26, in inner
    return func(*args, **kwargs)
  File "C:\Users\Sunny_Future\AppData\Roaming\Python\Python36\site-packages\django\db\backends\base\base.py", line 200, in connect
    self.connection = self.get_new_connection(conn_params)
  File "C:\Users\Sunny_Future\AppData\Roaming\Python\Python36\site-packages\django\utils\asyncio.py", line 26, in inner
    return func(*args, **kwargs)
  File "C:\Users\Sunny_Future\AppData\Roaming\Python\Python36\site-packages\django\db\backends\mysql\base.py", line 234, in get_new_connection
    return Database.connect(**conn_params)
  File "C:\Users\Sunny_Future\AppData\Roaming\Python\Python36\site-packages\pymysql\connections.py", line 353, in __init__
    self.connect()
  File "C:\Users\Sunny_Future\AppData\Roaming\Python\Python36\site-packages\pymysql\connections.py", line 664, in connect
    raise exc
django.db.utils.OperationalError: (2003, "Can't connect to MySQL server on '192.168.137.11' (timed out)")
ERROR 2021-01-30 16:19:05,240 basehttp 157 "GET /xadmin/host/hosts/ HTTP/1.1" 500 286654
INFO 2021-01-30 17:06:11,158 autoreload 240 F:\文档\code\pythonCode\hippo\hippo_api\hippo_api\apps\host\__init__.py changed, reloading.
INFO 2021-01-30 17:06:14,323 autoreload 617 Watching for file changes with StatReloader
INFO 2021-01-30 17:06:16,198 autoreload 617 Watching for file changes with StatReloader
INFO 2021-01-30 17:06:32,963 autoreload 617 Watching for file changes with StatReloader
INFO 2021-01-30 17:07:51,065 autoreload 617 Watching for file changes with StatReloader
INFO 2021-01-30 17:07:59,689 basehttp 157 "GET /xadmin/users/user/ HTTP/1.1" 200 33614
INFO 2021-01-30 17:07:59,845 basehttp 157 "GET /static/xadmin/vendor/bootstrap/css/bootstrap.css HTTP/1.1" 304 0
INFO 2021-01-30 17:07:59,884 basehttp 157 "GET /static/xadmin/vendor/font-awesome/css/font-awesome.css HTTP/1.1" 304 0
INFO 2021-01-30 17:07:59,896 basehttp 157 "GET /static/xadmin/css/xadmin.main.css HTTP/1.1" 304 0
INFO 2021-01-30 17:07:59,918 basehttp 157 "GET /static/xadmin/css/xadmin.responsive.css HTTP/1.1" 304 0
INFO 2021-01-30 17:07:59,919 basehttp 157 "GET /static/xadmin/css/xadmin.plugins.css HTTP/1.1" 304 0
INFO 2021-01-30 17:07:59,922 basehttp 157 "GET /static/xadmin/css/xadmin.form.css HTTP/1.1" 304 0
INFO 2021-01-30 17:07:59,922 basehttp 157 "GET /static/xadmin/vendor/jquery/jquery.js HTTP/1.1" 304 0
INFO 2021-01-30 17:07:59,926 basehttp 157 "GET /static/xadmin/js/xadmin.plugin.details.js HTTP/1.1" 304 0
INFO 2021-01-30 17:07:59,930 basehttp 157 "GET /static/xadmin/js/xadmin.plugin.bookmark.js HTTP/1.1" 304 0
INFO 2021-01-30 17:07:59,937 basehttp 157 "GET /static/xadmin/js/xadmin.plugin.filters.js HTTP/1.1" 304 0
INFO 2021-01-30 17:07:59,942 basehttp 157 "GET /static/xadmin/js/xadmin.plugin.actions.js HTTP/1.1" 304 0
INFO 2021-01-30 17:07:59,943 basehttp 157 "GET /static/xadmin/js/xadmin.page.list.js HTTP/1.1" 304 0
INFO 2021-01-30 17:07:59,945 basehttp 157 "GET /static/xadmin/vendor/jquery-ui/jquery.ui.core.js HTTP/1.1" 304 0
INFO 2021-01-30 17:07:59,949 basehttp 157 "GET /static/xadmin/js/xadmin.page.form.js HTTP/1.1" 304 0
INFO 2021-01-30 17:07:59,954 basehttp 157 "GET /static/xadmin/vendor/jquery-ui/jquery.ui.widget.js HTTP/1.1" 304 0
INFO 2021-01-30 17:07:59,959 basehttp 157 "GET /static/xadmin/vendor/jquery-ui/jquery.ui.mouse.js HTTP/1.1" 304 0
INFO 2021-01-30 17:07:59,961 basehttp 157 "GET /static/xadmin/vendor/jquery-ui/jquery.ui.sortable.js HTTP/1.1" 304 0
INFO 2021-01-30 17:07:59,964 basehttp 157 "GET /static/xadmin/js/xadmin.main.js HTTP/1.1" 304 0
INFO 2021-01-30 17:07:59,967 basehttp 157 "GET /static/xadmin/vendor/bootstrap/js/bootstrap.js HTTP/1.1" 304 0
INFO 2021-01-30 17:07:59,968 basehttp 157 "GET /static/xadmin/vendor/jquery-ui/jquery.ui.effect.js HTTP/1.1" 304 0
INFO 2021-01-30 17:07:59,971 basehttp 157 "GET /static/xadmin/js/xadmin.responsive.js HTTP/1.1" 304 0
INFO 2021-01-30 17:07:59,973 basehttp 157 "GET /static/xadmin/js/xadmin.plugin.themes.js HTTP/1.1" 304 0
INFO 2021-01-30 17:07:59,977 basehttp 157 "GET /xadmin/jsi18n/ HTTP/1.1" 200 7732
INFO 2021-01-30 17:08:00,492 basehttp 157 "GET /static/xadmin/vendor/font-awesome/fonts/fontawesome-webfont.woff?v=4.0.3 HTTP/1.1" 304 0
INFO 2021-01-30 17:26:34,313 autoreload 240 F:\文档\code\pythonCode\hippo\hippo_api\hippo_api\apps\users\__init__.py changed, reloading.
INFO 2021-01-30 17:26:34,325 autoreload 240 F:\文档\code\pythonCode\hippo\hippo_api\hippo_api\apps\users\__init__.py changed, reloading.
INFO 2021-01-30 17:26:36,350 autoreload 617 Watching for file changes with StatReloader
INFO 2021-01-30 17:26:36,350 autoreload 617 Watching for file changes with StatReloader
INFO 2021-01-30 17:26:39,065 autoreload 617 Watching for file changes with StatReloader
INFO 2021-01-30 17:27:19,054 autoreload 240 F:\文档\code\pythonCode\hippo\hippo_api\hippo_api\apps\users\__init__.py changed, reloading.
INFO 2021-01-30 17:27:21,104 autoreload 617 Watching for file changes with StatReloader
INFO 2021-01-30 17:27:22,228 autoreload 617 Watching for file changes with StatReloader
INFO 2021-01-30 17:27:32,367 basehttp 157 "GET /xadmin/users/user/ HTTP/1.1" 200 33621
INFO 2021-01-30 17:27:32,529 basehttp 157 "GET /xadmin/jsi18n/ HTTP/1.1" 200 7732
INFO 2021-01-30 17:27:36,324 basehttp 157 "GET /xadmin/users/user/ HTTP/1.1" 200 33621
INFO 2021-01-30 17:27:36,476 basehttp 157 "GET /xadmin/jsi18n/ HTTP/1.1" 200 7732
INFO 2021-01-30 17:27:49,317 autoreload 240 F:\文档\code\pythonCode\hippo\hippo_api\hippo_api\apps\users\apps.py changed, reloading.
INFO 2021-01-30 17:27:52,027 autoreload 617 Watching for file changes with StatReloader
INFO 2021-01-30 17:27:53,938 autoreload 617 Watching for file changes with StatReloader
INFO 2021-01-30 17:28:05,645 basehttp 157 "GET /xadmin/users/user/ HTTP/1.1" 200 33621
ERROR 2021-01-30 17:28:05,654 basehttp 157 "GET /xadmin/users/user/ HTTP/1.1" 500 59
INFO 2021-01-30 17:28:06,333 basehttp 157 "GET /xadmin/users/user/ HTTP/1.1" 200 33621
INFO 2021-01-30 17:28:06,397 basehttp 157 "GET /xadmin/jsi18n/ HTTP/1.1" 200 7732
INFO 2021-01-30 17:28:09,322 basehttp 157 "GET /xadmin/users/user/ HTTP/1.1" 200 33621
INFO 2021-01-30 17:28:09,469 basehttp 157 "GET /xadmin/jsi18n/ HTTP/1.1" 200 7732
INFO 2021-01-30 17:28:16,177 basehttp 157 "GET /xadmin/users/user/ HTTP/1.1" 200 33621
INFO 2021-01-30 17:28:16,221 basehttp 157 "GET /xadmin/jsi18n/ HTTP/1.1" 200 7732
INFO 2021-01-30 18:09:51,471 autoreload 240 F:\文档\code\pythonCode\hippo\hippo_api\hippo_api\settings\dev.py changed, reloading.
INFO 2021-01-30 18:09:51,517 autoreload 240 F:\文档\code\pythonCode\hippo\hippo_api\hippo_api\urls.py changed, reloading.
INFO 2021-01-30 18:09:55,691 autoreload 617 Watching for file changes with StatReloader
INFO 2021-01-30 18:09:55,693 autoreload 617 Watching for file changes with StatReloader
ERROR 2021-01-30 18:11:01,456 log 230 Internal Server Error: /users/login
Traceback (most recent call last):
  File "C:\Users\Sunny_Future\AppData\Roaming\Python\Python36\site-packages\django\core\handlers\exception.py", line 47, in inner
    response = get_response(request)
  File "C:\Users\Sunny_Future\AppData\Roaming\Python\Python36\site-packages\django\utils\deprecation.py", line 113, in __call__
    response = self.process_request(request)
  File "C:\Users\Sunny_Future\AppData\Roaming\Python\Python36\site-packages\django\middleware\common.py", line 54, in process_request
    path = self.get_full_path_with_slash(request)
  File "C:\Users\Sunny_Future\AppData\Roaming\Python\Python36\site-packages\django\middleware\common.py", line 94, in get_full_path_with_slash
    'url': request.get_host() + new_path,
RuntimeError: You called this URL via POST, but the URL doesn't end in a slash and you have APPEND_SLASH set. Django can't redirect to the slash URL while maintaining POST data. Change your form to point to api.hippo.com:8000/users/login/ (note the trailing slash), or set APPEND_SLASH=False in your Django settings.
ERROR 2021-01-30 18:11:01,459 basehttp 157 "POST /users/login HTTP/1.1" 500 71922
ERROR 2021-01-30 18:12:36,490 log 230 Internal Server Error: /users/login
Traceback (most recent call last):
  File "C:\Users\Sunny_Future\AppData\Roaming\Python\Python36\site-packages\django\core\handlers\exception.py", line 47, in inner
    response = get_response(request)
  File "C:\Users\Sunny_Future\AppData\Roaming\Python\Python36\site-packages\django\utils\deprecation.py", line 113, in __call__
    response = self.process_request(request)
  File "C:\Users\Sunny_Future\AppData\Roaming\Python\Python36\site-packages\django\middleware\common.py", line 54, in process_request
    path = self.get_full_path_with_slash(request)
  File "C:\Users\Sunny_Future\AppData\Roaming\Python\Python36\site-packages\django\middleware\common.py", line 94, in get_full_path_with_slash
    'url': request.get_host() + new_path,
RuntimeError: You called this URL via POST, but the URL doesn't end in a slash and you have APPEND_SLASH set. Django can't redirect to the slash URL while maintaining POST data. Change your form to point to api.hippo.com:8000/users/login/ (note the trailing slash), or set APPEND_SLASH=False in your Django settings.
ERROR 2021-01-30 18:12:36,493 basehttp 157 "POST /users/login HTTP/1.1" 500 71923
INFO 2021-01-30 18:13:24,194 autoreload 240 F:\文档\code\pythonCode\hippo\hippo_api\hippo_api\apps\users\urls.py changed, reloading.
INFO 2021-01-30 18:13:25,274 autoreload 240 F:\文档\code\pythonCode\hippo\hippo_api\hippo_api\apps\users\urls.py changed, reloading.
INFO 2021-01-30 18:13:27,730 autoreload 617 Watching for file changes with StatReloader
INFO 2021-01-30 18:13:28,762 autoreload 617 Watching for file changes with StatReloader
INFO 2021-01-30 18:14:03,088 basehttp 157 "GET /users/login HTTP/1.1" 301 0
ERROR 2021-01-30 18:14:03,894 log 230 Internal Server Error: /users/login/
Traceback (most recent call last):
  File "C:\Users\Sunny_Future\AppData\Roaming\Python\Python36\site-packages\rest_framework\views.py", line 506, in dispatch
    response = handler(request, *args, **kwargs)
  File "C:\Users\Sunny_Future\AppData\Roaming\Python\Python36\site-packages\rest_framework\views.py", line 167, in http_method_not_allowed
    raise exceptions.MethodNotAllowed(request.method)
rest_framework.exceptions.MethodNotAllowed: Method "GET" not allowed.

During handling of the above exception, another exception occurred:

Traceback (most recent call last):
  File "C:\Users\Sunny_Future\AppData\Roaming\Python\Python36\site-packages\rest_framework\settings.py", line 177, in import_from_string
    return import_string(val)
  File "C:\Users\Sunny_Future\AppData\Roaming\Python\Python36\site-packages\django\utils\module_loading.py", line 17, in import_string
    module = import_module(module_path)
  File "D:\Program files\python36\lib\importlib\__init__.py", line 126, in import_module
    return _bootstrap._gcd_import(name[level:], package, level)
  File "<frozen importlib._bootstrap>", line 994, in _gcd_import
  File "<frozen importlib._bootstrap>", line 971, in _find_and_load
  File "<frozen importlib._bootstrap>", line 941, in _find_and_load_unlocked
  File "<frozen importlib._bootstrap>", line 219, in _call_with_frames_removed
  File "<frozen importlib._bootstrap>", line 994, in _gcd_import
  File "<frozen importlib._bootstrap>", line 971, in _find_and_load
  File "<frozen importlib._bootstrap>", line 941, in _find_and_load_unlocked
  File "<frozen importlib._bootstrap>", line 219, in _call_with_frames_removed
  File "<frozen importlib._bootstrap>", line 994, in _gcd_import
  File "<frozen importlib._bootstrap>", line 971, in _find_and_load
  File "<frozen importlib._bootstrap>", line 953, in _find_and_load_unlocked
ModuleNotFoundError: No module named 'hippo02'

During handling of the above exception, another exception occurred:

Traceback (most recent call last):
  File "C:\Users\Sunny_Future\AppData\Roaming\Python\Python36\site-packages\django\core\handlers\exception.py", line 47, in inner
    response = get_response(request)
  File "C:\Users\Sunny_Future\AppData\Roaming\Python\Python36\site-packages\django\core\handlers\base.py", line 181, in _get_response
    response = wrapped_callback(request, *callback_args, **callback_kwargs)
  File "C:\Users\Sunny_Future\AppData\Roaming\Python\Python36\site-packages\django\views\decorators\csrf.py", line 54, in wrapped_view
    return view_func(*args, **kwargs)
  File "C:\Users\Sunny_Future\AppData\Roaming\Python\Python36\site-packages\django\views\generic\base.py", line 70, in view
    return self.dispatch(request, *args, **kwargs)
  File "C:\Users\Sunny_Future\AppData\Roaming\Python\Python36\site-packages\rest_framework\views.py", line 509, in dispatch
    response = self.handle_exception(exc)
  File "C:\Users\Sunny_Future\AppData\Roaming\Python\Python36\site-packages\rest_framework\views.py", line 463, in handle_exception
    exception_handler = self.get_exception_handler()
  File "C:\Users\Sunny_Future\AppData\Roaming\Python\Python36\site-packages\rest_framework\views.py", line 298, in get_exception_handler
    return self.settings.EXCEPTION_HANDLER
  File "C:\Users\Sunny_Future\AppData\Roaming\Python\Python36\site-packages\rest_framework\settings.py", line 225, in __getattr__
    val = perform_import(val, attr)
  File "C:\Users\Sunny_Future\AppData\Roaming\Python\Python36\site-packages\rest_framework\settings.py", line 166, in perform_import
    return import_from_string(val, setting_name)
  File "C:\Users\Sunny_Future\AppData\Roaming\Python\Python36\site-packages\rest_framework\settings.py", line 180, in import_from_string
    raise ImportError(msg)
ImportError: Could not import 'hippo02.utils.exceptions.custom_exception_handler' for API setting 'EXCEPTION_HANDLER'. ModuleNotFoundError: No module named 'hippo02'.
ERROR 2021-01-30 18:14:03,907 basehttp 157 "GET /users/login/ HTTP/1.1" 500 137827
INFO 2021-01-30 18:19:06,814 autoreload 240 F:\文档\code\pythonCode\hippo\hippo_api\hippo_api\settings\dev.py changed, reloading.
INFO 2021-01-30 18:19:09,106 autoreload 617 Watching for file changes with StatReloader
INFO 2021-01-30 18:19:10,520 autoreload 617 Watching for file changes with StatReloader
INFO 2021-01-30 18:19:31,033 autoreload 240 F:\文档\code\pythonCode\hippo\hippo_api\hippo_api\settings\dev.py changed, reloading.
INFO 2021-01-30 18:19:31,067 autoreload 240 F:\文档\code\pythonCode\hippo\hippo_api\hippo_api\settings\dev.py changed, reloading.
INFO 2021-01-30 18:19:34,506 autoreload 617 Watching for file changes with StatReloader
INFO 2021-01-30 18:19:34,507 autoreload 617 Watching for file changes with StatReloader
ERROR 2021-01-30 18:19:36,023 log 230 Internal Server Error: /users/login/
Traceback (most recent call last):
  File "C:\Users\Sunny_Future\AppData\Roaming\Python\Python36\site-packages\rest_framework\views.py", line 506, in dispatch
    response = handler(request, *args, **kwargs)
  File "C:\Users\Sunny_Future\AppData\Roaming\Python\Python36\site-packages\rest_framework\views.py", line 167, in http_method_not_allowed
    raise exceptions.MethodNotAllowed(request.method)
rest_framework.exceptions.MethodNotAllowed: Method "GET" not allowed.

During handling of the above exception, another exception occurred:

Traceback (most recent call last):
  File "C:\Users\Sunny_Future\AppData\Roaming\Python\Python36\site-packages\rest_framework\settings.py", line 177, in import_from_string
    return import_string(val)
  File "C:\Users\Sunny_Future\AppData\Roaming\Python\Python36\site-packages\django\utils\module_loading.py", line 17, in import_string
    module = import_module(module_path)
  File "D:\Program files\python36\lib\importlib\__init__.py", line 126, in import_module
    return _bootstrap._gcd_import(name[level:], package, level)
  File "<frozen importlib._bootstrap>", line 994, in _gcd_import
  File "<frozen importlib._bootstrap>", line 971, in _find_and_load
  File "<frozen importlib._bootstrap>", line 941, in _find_and_load_unlocked
  File "<frozen importlib._bootstrap>", line 219, in _call_with_frames_removed
  File "<frozen importlib._bootstrap>", line 994, in _gcd_import
  File "<frozen importlib._bootstrap>", line 971, in _find_and_load
  File "<frozen importlib._bootstrap>", line 941, in _find_and_load_unlocked
  File "<frozen importlib._bootstrap>", line 219, in _call_with_frames_removed
  File "<frozen importlib._bootstrap>", line 994, in _gcd_import
  File "<frozen importlib._bootstrap>", line 971, in _find_and_load
  File "<frozen importlib._bootstrap>", line 953, in _find_and_load_unlocked
ModuleNotFoundError: No module named 'hippo'

During handling of the above exception, another exception occurred:

Traceback (most recent call last):
  File "C:\Users\Sunny_Future\AppData\Roaming\Python\Python36\site-packages\django\core\handlers\exception.py", line 47, in inner
    response = get_response(request)
  File "C:\Users\Sunny_Future\AppData\Roaming\Python\Python36\site-packages\django\core\handlers\base.py", line 181, in _get_response
    response = wrapped_callback(request, *callback_args, **callback_kwargs)
  File "C:\Users\Sunny_Future\AppData\Roaming\Python\Python36\site-packages\django\views\decorators\csrf.py", line 54, in wrapped_view
    return view_func(*args, **kwargs)
  File "C:\Users\Sunny_Future\AppData\Roaming\Python\Python36\site-packages\django\views\generic\base.py", line 70, in view
    return self.dispatch(request, *args, **kwargs)
  File "C:\Users\Sunny_Future\AppData\Roaming\Python\Python36\site-packages\rest_framework\views.py", line 509, in dispatch
    response = self.handle_exception(exc)
  File "C:\Users\Sunny_Future\AppData\Roaming\Python\Python36\site-packages\rest_framework\views.py", line 463, in handle_exception
    exception_handler = self.get_exception_handler()
  File "C:\Users\Sunny_Future\AppData\Roaming\Python\Python36\site-packages\rest_framework\views.py", line 298, in get_exception_handler
    return self.settings.EXCEPTION_HANDLER
  File "C:\Users\Sunny_Future\AppData\Roaming\Python\Python36\site-packages\rest_framework\settings.py", line 225, in __getattr__
    val = perform_import(val, attr)
  File "C:\Users\Sunny_Future\AppData\Roaming\Python\Python36\site-packages\rest_framework\settings.py", line 166, in perform_import
    return import_from_string(val, setting_name)
  File "C:\Users\Sunny_Future\AppData\Roaming\Python\Python36\site-packages\rest_framework\settings.py", line 180, in import_from_string
    raise ImportError(msg)
ImportError: Could not import 'hippo.utils.exceptions.custom_exception_handler' for API setting 'EXCEPTION_HANDLER'. ModuleNotFoundError: No module named 'hippo'.
ERROR 2021-01-30 18:19:36,030 basehttp 157 "GET /users/login/ HTTP/1.1" 500 137894
INFO 2021-01-30 18:19:52,007 autoreload 240 F:\文档\code\pythonCode\hippo\hippo_api\hippo_api\settings\dev.py changed, reloading.
INFO 2021-01-30 18:19:54,009 autoreload 617 Watching for file changes with StatReloader
INFO 2021-01-30 18:19:55,259 autoreload 617 Watching for file changes with StatReloader
ERROR 2021-01-30 18:19:58,328 log 230 Internal Server Error: /users/login/
Traceback (most recent call last):
  File "C:\Users\Sunny_Future\AppData\Roaming\Python\Python36\site-packages\django\core\handlers\exception.py", line 47, in inner
    response = get_response(request)
  File "C:\Users\Sunny_Future\AppData\Roaming\Python\Python36\site-packages\django\core\handlers\base.py", line 204, in _get_response
    response = response.render()
  File "C:\Users\Sunny_Future\AppData\Roaming\Python\Python36\site-packages\django\template\response.py", line 105, in render
    self.content = self.rendered_content
  File "C:\Users\Sunny_Future\AppData\Roaming\Python\Python36\site-packages\rest_framework\response.py", line 70, in rendered_content
    ret = renderer.render(self.data, accepted_media_type, context)
  File "C:\Users\Sunny_Future\AppData\Roaming\Python\Python36\site-packages\rest_framework\renderers.py", line 723, in render
    template = loader.get_template(self.template)
  File "C:\Users\Sunny_Future\AppData\Roaming\Python\Python36\site-packages\django\template\loader.py", line 19, in get_template
    raise TemplateDoesNotExist(template_name, chain=chain)
django.template.exceptions.TemplateDoesNotExist: rest_framework/api.html
ERROR 2021-01-30 18:19:58,334 basehttp 157 "GET /users/login/ HTTP/1.1" 500 85196
ERROR 2021-01-30 18:20:05,510 log 230 Internal Server Error: /users/login
Traceback (most recent call last):
  File "C:\Users\Sunny_Future\AppData\Roaming\Python\Python36\site-packages\django\core\handlers\exception.py", line 47, in inner
    response = get_response(request)
  File "C:\Users\Sunny_Future\AppData\Roaming\Python\Python36\site-packages\django\utils\deprecation.py", line 113, in __call__
    response = self.process_request(request)
  File "C:\Users\Sunny_Future\AppData\Roaming\Python\Python36\site-packages\django\middleware\common.py", line 54, in process_request
    path = self.get_full_path_with_slash(request)
  File "C:\Users\Sunny_Future\AppData\Roaming\Python\Python36\site-packages\django\middleware\common.py", line 94, in get_full_path_with_slash
    'url': request.get_host() + new_path,
RuntimeError: You called this URL via POST, but the URL doesn't end in a slash and you have APPEND_SLASH set. Django can't redirect to the slash URL while maintaining POST data. Change your form to point to api.hippo.com:8000/users/login/ (note the trailing slash), or set APPEND_SLASH=False in your Django settings.
ERROR 2021-01-30 18:20:05,512 basehttp 157 "POST /users/login HTTP/1.1" 500 71925
WARNING 2021-01-30 18:20:25,961 log 230 Unsupported Media Type: /users/login/
WARNING 2021-01-30 18:20:25,962 basehttp 157 "POST /users/login/ HTTP/1.1" 415 62
WARNING 2021-01-30 18:20:49,656 log 230 Unsupported Media Type: /users/login/
WARNING 2021-01-30 18:20:49,656 basehttp 157 "POST /users/login/ HTTP/1.1" 415 62
WARNING 2021-01-30 18:20:57,039 log 230 Unsupported Media Type: /users/login/
WARNING 2021-01-30 18:20:57,040 basehttp 157 "POST /users/login/ HTTP/1.1" 415 62
WARNING 2021-01-30 18:22:12,552 log 230 Unsupported Media Type: /users/login/
WARNING 2021-01-30 18:22:12,553 basehttp 157 "POST /users/login/ HTTP/1.1" 415 62
INFO 2021-01-30 18:22:42,931 basehttp 157 "POST /users/login/ HTTP/1.1" 200 188
INFO 2021-01-30 18:23:02,902 basehttp 157 "POST /users/login/ HTTP/1.1" 200 188
WARNING 2021-01-30 18:23:25,164 log 230 Bad Request: /users/login/
WARNING 2021-01-30 18:23:25,165 basehttp 157 "POST /users/login/ HTTP/1.1" 400 68
INFO 2021-01-30 18:24:56,208 basehttp 157 "POST /users/login/ HTTP/1.1" 200 188
ERROR 2021-01-30 18:59:41,972 log 230 Internal Server Error: /xadmin/host/hosts/
Traceback (most recent call last):
  File "C:\Users\Sunny_Future\AppData\Roaming\Python\Python36\site-packages\django\contrib\sessions\backends\base.py", line 233, in _get_session
    return self._session_cache
AttributeError: 'SessionStore' object has no attribute '_session_cache'

During handling of the above exception, another exception occurred:

Traceback (most recent call last):
  File "C:\Users\Sunny_Future\AppData\Roaming\Python\Python36\site-packages\pymysql\connections.py", line 614, in connect
    (self.host, self.port), self.connect_timeout, **kwargs
  File "D:\Program files\python36\lib\socket.py", line 724, in create_connection
    raise err
  File "D:\Program files\python36\lib\socket.py", line 713, in create_connection
    sock.connect(sa)
socket.timeout: timed out

During handling of the above exception, another exception occurred:

Traceback (most recent call last):
  File "C:\Users\Sunny_Future\AppData\Roaming\Python\Python36\site-packages\django\db\backends\base\base.py", line 219, in ensure_connection
    self.connect()
  File "C:\Users\Sunny_Future\AppData\Roaming\Python\Python36\site-packages\django\utils\asyncio.py", line 26, in inner
    return func(*args, **kwargs)
  File "C:\Users\Sunny_Future\AppData\Roaming\Python\Python36\site-packages\django\db\backends\base\base.py", line 200, in connect
    self.connection = self.get_new_connection(conn_params)
  File "C:\Users\Sunny_Future\AppData\Roaming\Python\Python36\site-packages\django\utils\asyncio.py", line 26, in inner
    return func(*args, **kwargs)
  File "C:\Users\Sunny_Future\AppData\Roaming\Python\Python36\site-packages\django\db\backends\mysql\base.py", line 234, in get_new_connection
    return Database.connect(**conn_params)
  File "C:\Users\Sunny_Future\AppData\Roaming\Python\Python36\site-packages\pymysql\connections.py", line 353, in __init__
    self.connect()
  File "C:\Users\Sunny_Future\AppData\Roaming\Python\Python36\site-packages\pymysql\connections.py", line 664, in connect
    raise exc
pymysql.err.OperationalError: (2003, "Can't connect to MySQL server on '192.168.137.11' (timed out)")

The above exception was the direct cause of the following exception:

Traceback (most recent call last):
  File "C:\Users\Sunny_Future\AppData\Roaming\Python\Python36\site-packages\django\core\handlers\exception.py", line 47, in inner
    response = get_response(request)
  File "C:\Users\Sunny_Future\AppData\Roaming\Python\Python36\site-packages\django\core\handlers\base.py", line 181, in _get_response
    response = wrapped_callback(request, *callback_args, **callback_kwargs)
  File "C:\Users\Sunny_Future\AppData\Roaming\Python\Python36\site-packages\xadmin\sites.py", line 300, in wrapper
    return self.admin_view(view, cacheable)(*args, **kwargs)
  File "C:\Users\Sunny_Future\AppData\Roaming\Python\Python36\site-packages\django\views\decorators\cache.py", line 44, in _wrapped_view_func
    response = view_func(request, *args, **kwargs)
  File "C:\Users\Sunny_Future\AppData\Roaming\Python\Python36\site-packages\xadmin\sites.py", line 206, in inner
    if not self.has_permission(request) and getattr(view, 'need_site_permission', True):
  File "C:\Users\Sunny_Future\AppData\Roaming\Python\Python36\site-packages\xadmin\sites.py", line 161, in has_permission
    return request.user.is_active and request.user.is_staff
  File "C:\Users\Sunny_Future\AppData\Roaming\Python\Python36\site-packages\django\utils\functional.py", line 240, in inner
    self._setup()
  File "C:\Users\Sunny_Future\AppData\Roaming\Python\Python36\site-packages\django\utils\functional.py", line 376, in _setup
    self._wrapped = self._setupfunc()
  File "C:\Users\Sunny_Future\AppData\Roaming\Python\Python36\site-packages\django\contrib\auth\middleware.py", line 23, in <lambda>
    request.user = SimpleLazyObject(lambda: get_user(request))
  File "C:\Users\Sunny_Future\AppData\Roaming\Python\Python36\site-packages\django\contrib\auth\middleware.py", line 11, in get_user
    request._cached_user = auth.get_user(request)
  File "C:\Users\Sunny_Future\AppData\Roaming\Python\Python36\site-packages\django\contrib\auth\__init__.py", line 174, in get_user
    user_id = _get_user_session_key(request)
  File "C:\Users\Sunny_Future\AppData\Roaming\Python\Python36\site-packages\django\contrib\auth\__init__.py", line 58, in _get_user_session_key
    return get_user_model()._meta.pk.to_python(request.session[SESSION_KEY])
  File "C:\Users\Sunny_Future\AppData\Roaming\Python\Python36\site-packages\django\contrib\sessions\backends\base.py", line 65, in __getitem__
    return self._session[key]
  File "C:\Users\Sunny_Future\AppData\Roaming\Python\Python36\site-packages\django\contrib\sessions\backends\base.py", line 238, in _get_session
    self._session_cache = self.load()
  File "C:\Users\Sunny_Future\AppData\Roaming\Python\Python36\site-packages\django\contrib\sessions\backends\db.py", line 43, in load
    s = self._get_session_from_db()
  File "C:\Users\Sunny_Future\AppData\Roaming\Python\Python36\site-packages\django\contrib\sessions\backends\db.py", line 34, in _get_session_from_db
    expire_date__gt=timezone.now()
  File "C:\Users\Sunny_Future\AppData\Roaming\Python\Python36\site-packages\django\db\models\manager.py", line 85, in manager_method
    return getattr(self.get_queryset(), name)(*args, **kwargs)
  File "C:\Users\Sunny_Future\AppData\Roaming\Python\Python36\site-packages\django\db\models\query.py", line 425, in get
    num = len(clone)
  File "C:\Users\Sunny_Future\AppData\Roaming\Python\Python36\site-packages\django\db\models\query.py", line 269, in __len__
    self._fetch_all()
  File "C:\Users\Sunny_Future\AppData\Roaming\Python\Python36\site-packages\django\db\models\query.py", line 1308, in _fetch_all
    self._result_cache = list(self._iterable_class(self))
  File "C:\Users\Sunny_Future\AppData\Roaming\Python\Python36\site-packages\django\db\models\query.py", line 53, in __iter__
    results = compiler.execute_sql(chunked_fetch=self.chunked_fetch, chunk_size=self.chunk_size)
  File "C:\Users\Sunny_Future\AppData\Roaming\Python\Python36\site-packages\django\db\models\sql\compiler.py", line 1154, in execute_sql
    cursor = self.connection.cursor()
  File "C:\Users\Sunny_Future\AppData\Roaming\Python\Python36\site-packages\django\utils\asyncio.py", line 26, in inner
    return func(*args, **kwargs)
  File "C:\Users\Sunny_Future\AppData\Roaming\Python\Python36\site-packages\django\db\backends\base\base.py", line 259, in cursor
    return self._cursor()
  File "C:\Users\Sunny_Future\AppData\Roaming\Python\Python36\site-packages\django\db\backends\base\base.py", line 235, in _cursor
    self.ensure_connection()
  File "C:\Users\Sunny_Future\AppData\Roaming\Python\Python36\site-packages\django\utils\asyncio.py", line 26, in inner
    return func(*args, **kwargs)
  File "C:\Users\Sunny_Future\AppData\Roaming\Python\Python36\site-packages\django\db\backends\base\base.py", line 219, in ensure_connection
    self.connect()
  File "C:\Users\Sunny_Future\AppData\Roaming\Python\Python36\site-packages\django\db\utils.py", line 90, in __exit__
    raise dj_exc_value.with_traceback(traceback) from exc_value
  File "C:\Users\Sunny_Future\AppData\Roaming\Python\Python36\site-packages\django\db\backends\base\base.py", line 219, in ensure_connection
    self.connect()
  File "C:\Users\Sunny_Future\AppData\Roaming\Python\Python36\site-packages\django\utils\asyncio.py", line 26, in inner
    return func(*args, **kwargs)
  File "C:\Users\Sunny_Future\AppData\Roaming\Python\Python36\site-packages\django\db\backends\base\base.py", line 200, in connect
    self.connection = self.get_new_connection(conn_params)
  File "C:\Users\Sunny_Future\AppData\Roaming\Python\Python36\site-packages\django\utils\asyncio.py", line 26, in inner
    return func(*args, **kwargs)
  File "C:\Users\Sunny_Future\AppData\Roaming\Python\Python36\site-packages\django\db\backends\mysql\base.py", line 234, in get_new_connection
    return Database.connect(**conn_params)
  File "C:\Users\Sunny_Future\AppData\Roaming\Python\Python36\site-packages\pymysql\connections.py", line 353, in __init__
    self.connect()
  File "C:\Users\Sunny_Future\AppData\Roaming\Python\Python36\site-packages\pymysql\connections.py", line 664, in connect
    raise exc
django.db.utils.OperationalError: (2003, "Can't connect to MySQL server on '192.168.137.11' (timed out)")
ERROR 2021-01-30 18:59:41,979 basehttp 157 "GET /xadmin/host/hosts/ HTTP/1.1" 500 286819
ERROR 2021-01-30 20:01:49,494 log 230 Internal Server Error: /xadmin/host/hosts/
Traceback (most recent call last):
  File "C:\Users\Sunny_Future\AppData\Roaming\Python\Python36\site-packages\django\contrib\sessions\backends\base.py", line 233, in _get_session
    return self._session_cache
AttributeError: 'SessionStore' object has no attribute '_session_cache'

During handling of the above exception, another exception occurred:

Traceback (most recent call last):
  File "C:\Users\Sunny_Future\AppData\Roaming\Python\Python36\site-packages\pymysql\connections.py", line 614, in connect
    (self.host, self.port), self.connect_timeout, **kwargs
  File "D:\Program files\python36\lib\socket.py", line 724, in create_connection
    raise err
  File "D:\Program files\python36\lib\socket.py", line 713, in create_connection
    sock.connect(sa)
socket.timeout: timed out

During handling of the above exception, another exception occurred:

Traceback (most recent call last):
  File "C:\Users\Sunny_Future\AppData\Roaming\Python\Python36\site-packages\django\db\backends\base\base.py", line 219, in ensure_connection
    self.connect()
  File "C:\Users\Sunny_Future\AppData\Roaming\Python\Python36\site-packages\django\utils\asyncio.py", line 26, in inner
    return func(*args, **kwargs)
  File "C:\Users\Sunny_Future\AppData\Roaming\Python\Python36\site-packages\django\db\backends\base\base.py", line 200, in connect
    self.connection = self.get_new_connection(conn_params)
  File "C:\Users\Sunny_Future\AppData\Roaming\Python\Python36\site-packages\django\utils\asyncio.py", line 26, in inner
    return func(*args, **kwargs)
  File "C:\Users\Sunny_Future\AppData\Roaming\Python\Python36\site-packages\django\db\backends\mysql\base.py", line 234, in get_new_connection
    return Database.connect(**conn_params)
  File "C:\Users\Sunny_Future\AppData\Roaming\Python\Python36\site-packages\pymysql\connections.py", line 353, in __init__
    self.connect()
  File "C:\Users\Sunny_Future\AppData\Roaming\Python\Python36\site-packages\pymysql\connections.py", line 664, in connect
    raise exc
pymysql.err.OperationalError: (2003, "Can't connect to MySQL server on '192.168.137.11' (timed out)")

The above exception was the direct cause of the following exception:

Traceback (most recent call last):
  File "C:\Users\Sunny_Future\AppData\Roaming\Python\Python36\site-packages\django\core\handlers\exception.py", line 47, in inner
    response = get_response(request)
  File "C:\Users\Sunny_Future\AppData\Roaming\Python\Python36\site-packages\django\core\handlers\base.py", line 181, in _get_response
    response = wrapped_callback(request, *callback_args, **callback_kwargs)
  File "C:\Users\Sunny_Future\AppData\Roaming\Python\Python36\site-packages\xadmin\sites.py", line 300, in wrapper
    return self.admin_view(view, cacheable)(*args, **kwargs)
  File "C:\Users\Sunny_Future\AppData\Roaming\Python\Python36\site-packages\django\views\decorators\cache.py", line 44, in _wrapped_view_func
    response = view_func(request, *args, **kwargs)
  File "C:\Users\Sunny_Future\AppData\Roaming\Python\Python36\site-packages\xadmin\sites.py", line 206, in inner
    if not self.has_permission(request) and getattr(view, 'need_site_permission', True):
  File "C:\Users\Sunny_Future\AppData\Roaming\Python\Python36\site-packages\xadmin\sites.py", line 161, in has_permission
    return request.user.is_active and request.user.is_staff
  File "C:\Users\Sunny_Future\AppData\Roaming\Python\Python36\site-packages\django\utils\functional.py", line 240, in inner
    self._setup()
  File "C:\Users\Sunny_Future\AppData\Roaming\Python\Python36\site-packages\django\utils\functional.py", line 376, in _setup
    self._wrapped = self._setupfunc()
  File "C:\Users\Sunny_Future\AppData\Roaming\Python\Python36\site-packages\django\contrib\auth\middleware.py", line 23, in <lambda>
    request.user = SimpleLazyObject(lambda: get_user(request))
  File "C:\Users\Sunny_Future\AppData\Roaming\Python\Python36\site-packages\django\contrib\auth\middleware.py", line 11, in get_user
    request._cached_user = auth.get_user(request)
  File "C:\Users\Sunny_Future\AppData\Roaming\Python\Python36\site-packages\django\contrib\auth\__init__.py", line 174, in get_user
    user_id = _get_user_session_key(request)
  File "C:\Users\Sunny_Future\AppData\Roaming\Python\Python36\site-packages\django\contrib\auth\__init__.py", line 58, in _get_user_session_key
    return get_user_model()._meta.pk.to_python(request.session[SESSION_KEY])
  File "C:\Users\Sunny_Future\AppData\Roaming\Python\Python36\site-packages\django\contrib\sessions\backends\base.py", line 65, in __getitem__
    return self._session[key]
  File "C:\Users\Sunny_Future\AppData\Roaming\Python\Python36\site-packages\django\contrib\sessions\backends\base.py", line 238, in _get_session
    self._session_cache = self.load()
  File "C:\Users\Sunny_Future\AppData\Roaming\Python\Python36\site-packages\django\contrib\sessions\backends\db.py", line 43, in load
    s = self._get_session_from_db()
  File "C:\Users\Sunny_Future\AppData\Roaming\Python\Python36\site-packages\django\contrib\sessions\backends\db.py", line 34, in _get_session_from_db
    expire_date__gt=timezone.now()
  File "C:\Users\Sunny_Future\AppData\Roaming\Python\Python36\site-packages\django\db\models\manager.py", line 85, in manager_method
    return getattr(self.get_queryset(), name)(*args, **kwargs)
  File "C:\Users\Sunny_Future\AppData\Roaming\Python\Python36\site-packages\django\db\models\query.py", line 425, in get
    num = len(clone)
  File "C:\Users\Sunny_Future\AppData\Roaming\Python\Python36\site-packages\django\db\models\query.py", line 269, in __len__
    self._fetch_all()
  File "C:\Users\Sunny_Future\AppData\Roaming\Python\Python36\site-packages\django\db\models\query.py", line 1308, in _fetch_all
    self._result_cache = list(self._iterable_class(self))
  File "C:\Users\Sunny_Future\AppData\Roaming\Python\Python36\site-packages\django\db\models\query.py", line 53, in __iter__
    results = compiler.execute_sql(chunked_fetch=self.chunked_fetch, chunk_size=self.chunk_size)
  File "C:\Users\Sunny_Future\AppData\Roaming\Python\Python36\site-packages\django\db\models\sql\compiler.py", line 1154, in execute_sql
    cursor = self.connection.cursor()
  File "C:\Users\Sunny_Future\AppData\Roaming\Python\Python36\site-packages\django\utils\asyncio.py", line 26, in inner
    return func(*args, **kwargs)
  File "C:\Users\Sunny_Future\AppData\Roaming\Python\Python36\site-packages\django\db\backends\base\base.py", line 259, in cursor
    return self._cursor()
  File "C:\Users\Sunny_Future\AppData\Roaming\Python\Python36\site-packages\django\db\backends\base\base.py", line 235, in _cursor
    self.ensure_connection()
  File "C:\Users\Sunny_Future\AppData\Roaming\Python\Python36\site-packages\django\utils\asyncio.py", line 26, in inner
    return func(*args, **kwargs)
  File "C:\Users\Sunny_Future\AppData\Roaming\Python\Python36\site-packages\django\db\backends\base\base.py", line 219, in ensure_connection
    self.connect()
  File "C:\Users\Sunny_Future\AppData\Roaming\Python\Python36\site-packages\django\db\utils.py", line 90, in __exit__
    raise dj_exc_value.with_traceback(traceback) from exc_value
  File "C:\Users\Sunny_Future\AppData\Roaming\Python\Python36\site-packages\django\db\backends\base\base.py", line 219, in ensure_connection
    self.connect()
  File "C:\Users\Sunny_Future\AppData\Roaming\Python\Python36\site-packages\django\utils\asyncio.py", line 26, in inner
    return func(*args, **kwargs)
  File "C:\Users\Sunny_Future\AppData\Roaming\Python\Python36\site-packages\django\db\backends\base\base.py", line 200, in connect
    self.connection = self.get_new_connection(conn_params)
  File "C:\Users\Sunny_Future\AppData\Roaming\Python\Python36\site-packages\django\utils\asyncio.py", line 26, in inner
    return func(*args, **kwargs)
  File "C:\Users\Sunny_Future\AppData\Roaming\Python\Python36\site-packages\django\db\backends\mysql\base.py", line 234, in get_new_connection
    return Database.connect(**conn_params)
  File "C:\Users\Sunny_Future\AppData\Roaming\Python\Python36\site-packages\pymysql\connections.py", line 353, in __init__
    self.connect()
  File "C:\Users\Sunny_Future\AppData\Roaming\Python\Python36\site-packages\pymysql\connections.py", line 664, in connect
    raise exc
django.db.utils.OperationalError: (2003, "Can't connect to MySQL server on '192.168.137.11' (timed out)")
ERROR 2021-01-30 20:01:49,501 basehttp 157 "GET /xadmin/host/hosts/ HTTP/1.1" 500 286171
ERROR 2021-01-30 20:01:49,502 basehttp 157 "GET /xadmin/host/hosts/ HTTP/1.1" 500 59
ERROR 2021-01-30 20:01:52,243 log 230 Internal Server Error: /xadmin/host/hosts/
Traceback (most recent call last):
  File "C:\Users\Sunny_Future\AppData\Roaming\Python\Python36\site-packages\django\contrib\sessions\backends\base.py", line 233, in _get_session
    return self._session_cache
AttributeError: 'SessionStore' object has no attribute '_session_cache'

During handling of the above exception, another exception occurred:

Traceback (most recent call last):
  File "C:\Users\Sunny_Future\AppData\Roaming\Python\Python36\site-packages\pymysql\connections.py", line 614, in connect
    (self.host, self.port), self.connect_timeout, **kwargs
  File "D:\Program files\python36\lib\socket.py", line 724, in create_connection
    raise err
  File "D:\Program files\python36\lib\socket.py", line 713, in create_connection
    sock.connect(sa)
socket.timeout: timed out

During handling of the above exception, another exception occurred:

Traceback (most recent call last):
  File "C:\Users\Sunny_Future\AppData\Roaming\Python\Python36\site-packages\django\db\backends\base\base.py", line 219, in ensure_connection
    self.connect()
  File "C:\Users\Sunny_Future\AppData\Roaming\Python\Python36\site-packages\django\utils\asyncio.py", line 26, in inner
    return func(*args, **kwargs)
  File "C:\Users\Sunny_Future\AppData\Roaming\Python\Python36\site-packages\django\db\backends\base\base.py", line 200, in connect
    self.connection = self.get_new_connection(conn_params)
  File "C:\Users\Sunny_Future\AppData\Roaming\Python\Python36\site-packages\django\utils\asyncio.py", line 26, in inner
    return func(*args, **kwargs)
  File "C:\Users\Sunny_Future\AppData\Roaming\Python\Python36\site-packages\django\db\backends\mysql\base.py", line 234, in get_new_connection
    return Database.connect(**conn_params)
  File "C:\Users\Sunny_Future\AppData\Roaming\Python\Python36\site-packages\pymysql\connections.py", line 353, in __init__
    self.connect()
  File "C:\Users\Sunny_Future\AppData\Roaming\Python\Python36\site-packages\pymysql\connections.py", line 664, in connect
    raise exc
pymysql.err.OperationalError: (2003, "Can't connect to MySQL server on '192.168.137.11' (timed out)")

The above exception was the direct cause of the following exception:

Traceback (most recent call last):
  File "C:\Users\Sunny_Future\AppData\Roaming\Python\Python36\site-packages\django\core\handlers\exception.py", line 47, in inner
    response = get_response(request)
  File "C:\Users\Sunny_Future\AppData\Roaming\Python\Python36\site-packages\django\core\handlers\base.py", line 181, in _get_response
    response = wrapped_callback(request, *callback_args, **callback_kwargs)
  File "C:\Users\Sunny_Future\AppData\Roaming\Python\Python36\site-packages\xadmin\sites.py", line 300, in wrapper
    return self.admin_view(view, cacheable)(*args, **kwargs)
  File "C:\Users\Sunny_Future\AppData\Roaming\Python\Python36\site-packages\django\views\decorators\cache.py", line 44, in _wrapped_view_func
    response = view_func(request, *args, **kwargs)
  File "C:\Users\Sunny_Future\AppData\Roaming\Python\Python36\site-packages\xadmin\sites.py", line 206, in inner
    if not self.has_permission(request) and getattr(view, 'need_site_permission', True):
  File "C:\Users\Sunny_Future\AppData\Roaming\Python\Python36\site-packages\xadmin\sites.py", line 161, in has_permission
    return request.user.is_active and request.user.is_staff
  File "C:\Users\Sunny_Future\AppData\Roaming\Python\Python36\site-packages\django\utils\functional.py", line 240, in inner
    self._setup()
  File "C:\Users\Sunny_Future\AppData\Roaming\Python\Python36\site-packages\django\utils\functional.py", line 376, in _setup
    self._wrapped = self._setupfunc()
  File "C:\Users\Sunny_Future\AppData\Roaming\Python\Python36\site-packages\django\contrib\auth\middleware.py", line 23, in <lambda>
    request.user = SimpleLazyObject(lambda: get_user(request))
  File "C:\Users\Sunny_Future\AppData\Roaming\Python\Python36\site-packages\django\contrib\auth\middleware.py", line 11, in get_user
    request._cached_user = auth.get_user(request)
  File "C:\Users\Sunny_Future\AppData\Roaming\Python\Python36\site-packages\django\contrib\auth\__init__.py", line 174, in get_user
    user_id = _get_user_session_key(request)
  File "C:\Users\Sunny_Future\AppData\Roaming\Python\Python36\site-packages\django\contrib\auth\__init__.py", line 58, in _get_user_session_key
    return get_user_model()._meta.pk.to_python(request.session[SESSION_KEY])
  File "C:\Users\Sunny_Future\AppData\Roaming\Python\Python36\site-packages\django\contrib\sessions\backends\base.py", line 65, in __getitem__
    return self._session[key]
  File "C:\Users\Sunny_Future\AppData\Roaming\Python\Python36\site-packages\django\contrib\sessions\backends\base.py", line 238, in _get_session
    self._session_cache = self.load()
  File "C:\Users\Sunny_Future\AppData\Roaming\Python\Python36\site-packages\django\contrib\sessions\backends\db.py", line 43, in load
    s = self._get_session_from_db()
  File "C:\Users\Sunny_Future\AppData\Roaming\Python\Python36\site-packages\django\contrib\sessions\backends\db.py", line 34, in _get_session_from_db
    expire_date__gt=timezone.now()
  File "C:\Users\Sunny_Future\AppData\Roaming\Python\Python36\site-packages\django\db\models\manager.py", line 85, in manager_method
    return getattr(self.get_queryset(), name)(*args, **kwargs)
  File "C:\Users\Sunny_Future\AppData\Roaming\Python\Python36\site-packages\django\db\models\query.py", line 425, in get
    num = len(clone)
  File "C:\Users\Sunny_Future\AppData\Roaming\Python\Python36\site-packages\django\db\models\query.py", line 269, in __len__
    self._fetch_all()
  File "C:\Users\Sunny_Future\AppData\Roaming\Python\Python36\site-packages\django\db\models\query.py", line 1308, in _fetch_all
    self._result_cache = list(self._iterable_class(self))
  File "C:\Users\Sunny_Future\AppData\Roaming\Python\Python36\site-packages\django\db\models\query.py", line 53, in __iter__
    results = compiler.execute_sql(chunked_fetch=self.chunked_fetch, chunk_size=self.chunk_size)
  File "C:\Users\Sunny_Future\AppData\Roaming\Python\Python36\site-packages\django\db\models\sql\compiler.py", line 1154, in execute_sql
    cursor = self.connection.cursor()
  File "C:\Users\Sunny_Future\AppData\Roaming\Python\Python36\site-packages\django\utils\asyncio.py", line 26, in inner
    return func(*args, **kwargs)
  File "C:\Users\Sunny_Future\AppData\Roaming\Python\Python36\site-packages\django\db\backends\base\base.py", line 259, in cursor
    return self._cursor()
  File "C:\Users\Sunny_Future\AppData\Roaming\Python\Python36\site-packages\django\db\backends\base\base.py", line 235, in _cursor
    self.ensure_connection()
  File "C:\Users\Sunny_Future\AppData\Roaming\Python\Python36\site-packages\django\utils\asyncio.py", line 26, in inner
    return func(*args, **kwargs)
  File "C:\Users\Sunny_Future\AppData\Roaming\Python\Python36\site-packages\django\db\backends\base\base.py", line 219, in ensure_connection
    self.connect()
  File "C:\Users\Sunny_Future\AppData\Roaming\Python\Python36\site-packages\django\db\utils.py", line 90, in __exit__
    raise dj_exc_value.with_traceback(traceback) from exc_value
  File "C:\Users\Sunny_Future\AppData\Roaming\Python\Python36\site-packages\django\db\backends\base\base.py", line 219, in ensure_connection
    self.connect()
  File "C:\Users\Sunny_Future\AppData\Roaming\Python\Python36\site-packages\django\utils\asyncio.py", line 26, in inner
    return func(*args, **kwargs)
  File "C:\Users\Sunny_Future\AppData\Roaming\Python\Python36\site-packages\django\db\backends\base\base.py", line 200, in connect
    self.connection = self.get_new_connection(conn_params)
  File "C:\Users\Sunny_Future\AppData\Roaming\Python\Python36\site-packages\django\utils\asyncio.py", line 26, in inner
    return func(*args, **kwargs)
  File "C:\Users\Sunny_Future\AppData\Roaming\Python\Python36\site-packages\django\db\backends\mysql\base.py", line 234, in get_new_connection
    return Database.connect(**conn_params)
  File "C:\Users\Sunny_Future\AppData\Roaming\Python\Python36\site-packages\pymysql\connections.py", line 353, in __init__
    self.connect()
  File "C:\Users\Sunny_Future\AppData\Roaming\Python\Python36\site-packages\pymysql\connections.py", line 664, in connect
    raise exc
django.db.utils.OperationalError: (2003, "Can't connect to MySQL server on '192.168.137.11' (timed out)")
ERROR 2021-01-30 20:01:52,249 basehttp 157 "GET /xadmin/host/hosts/ HTTP/1.1" 500 286171
ERROR 2021-01-30 20:01:52,250 basehttp 157 "GET /xadmin/host/hosts/ HTTP/1.1" 500 59
ERROR 2021-01-30 20:01:55,372 log 230 Internal Server Error: /xadmin/host/hosts/
Traceback (most recent call last):
  File "C:\Users\Sunny_Future\AppData\Roaming\Python\Python36\site-packages\django\contrib\sessions\backends\base.py", line 233, in _get_session
    return self._session_cache
AttributeError: 'SessionStore' object has no attribute '_session_cache'

During handling of the above exception, another exception occurred:

Traceback (most recent call last):
  File "C:\Users\Sunny_Future\AppData\Roaming\Python\Python36\site-packages\pymysql\connections.py", line 614, in connect
    (self.host, self.port), self.connect_timeout, **kwargs
  File "D:\Program files\python36\lib\socket.py", line 724, in create_connection
    raise err
  File "D:\Program files\python36\lib\socket.py", line 713, in create_connection
    sock.connect(sa)
socket.timeout: timed out

During handling of the above exception, another exception occurred:

Traceback (most recent call last):
  File "C:\Users\Sunny_Future\AppData\Roaming\Python\Python36\site-packages\django\db\backends\base\base.py", line 219, in ensure_connection
    self.connect()
  File "C:\Users\Sunny_Future\AppData\Roaming\Python\Python36\site-packages\django\utils\asyncio.py", line 26, in inner
    return func(*args, **kwargs)
  File "C:\Users\Sunny_Future\AppData\Roaming\Python\Python36\site-packages\django\db\backends\base\base.py", line 200, in connect
    self.connection = self.get_new_connection(conn_params)
  File "C:\Users\Sunny_Future\AppData\Roaming\Python\Python36\site-packages\django\utils\asyncio.py", line 26, in inner
    return func(*args, **kwargs)
  File "C:\Users\Sunny_Future\AppData\Roaming\Python\Python36\site-packages\django\db\backends\mysql\base.py", line 234, in get_new_connection
    return Database.connect(**conn_params)
  File "C:\Users\Sunny_Future\AppData\Roaming\Python\Python36\site-packages\pymysql\connections.py", line 353, in __init__
    self.connect()
  File "C:\Users\Sunny_Future\AppData\Roaming\Python\Python36\site-packages\pymysql\connections.py", line 664, in connect
    raise exc
pymysql.err.OperationalError: (2003, "Can't connect to MySQL server on '192.168.137.11' (timed out)")

The above exception was the direct cause of the following exception:

Traceback (most recent call last):
  File "C:\Users\Sunny_Future\AppData\Roaming\Python\Python36\site-packages\django\core\handlers\exception.py", line 47, in inner
    response = get_response(request)
  File "C:\Users\Sunny_Future\AppData\Roaming\Python\Python36\site-packages\django\core\handlers\base.py", line 181, in _get_response
    response = wrapped_callback(request, *callback_args, **callback_kwargs)
  File "C:\Users\Sunny_Future\AppData\Roaming\Python\Python36\site-packages\xadmin\sites.py", line 300, in wrapper
    return self.admin_view(view, cacheable)(*args, **kwargs)
  File "C:\Users\Sunny_Future\AppData\Roaming\Python\Python36\site-packages\django\views\decorators\cache.py", line 44, in _wrapped_view_func
    response = view_func(request, *args, **kwargs)
  File "C:\Users\Sunny_Future\AppData\Roaming\Python\Python36\site-packages\xadmin\sites.py", line 206, in inner
    if not self.has_permission(request) and getattr(view, 'need_site_permission', True):
  File "C:\Users\Sunny_Future\AppData\Roaming\Python\Python36\site-packages\xadmin\sites.py", line 161, in has_permission
    return request.user.is_active and request.user.is_staff
  File "C:\Users\Sunny_Future\AppData\Roaming\Python\Python36\site-packages\django\utils\functional.py", line 240, in inner
    self._setup()
  File "C:\Users\Sunny_Future\AppData\Roaming\Python\Python36\site-packages\django\utils\functional.py", line 376, in _setup
    self._wrapped = self._setupfunc()
  File "C:\Users\Sunny_Future\AppData\Roaming\Python\Python36\site-packages\django\contrib\auth\middleware.py", line 23, in <lambda>
    request.user = SimpleLazyObject(lambda: get_user(request))
  File "C:\Users\Sunny_Future\AppData\Roaming\Python\Python36\site-packages\django\contrib\auth\middleware.py", line 11, in get_user
    request._cached_user = auth.get_user(request)
  File "C:\Users\Sunny_Future\AppData\Roaming\Python\Python36\site-packages\django\contrib\auth\__init__.py", line 174, in get_user
    user_id = _get_user_session_key(request)
  File "C:\Users\Sunny_Future\AppData\Roaming\Python\Python36\site-packages\django\contrib\auth\__init__.py", line 58, in _get_user_session_key
    return get_user_model()._meta.pk.to_python(request.session[SESSION_KEY])
  File "C:\Users\Sunny_Future\AppData\Roaming\Python\Python36\site-packages\django\contrib\sessions\backends\base.py", line 65, in __getitem__
    return self._session[key]
  File "C:\Users\Sunny_Future\AppData\Roaming\Python\Python36\site-packages\django\contrib\sessions\backends\base.py", line 238, in _get_session
    self._session_cache = self.load()
  File "C:\Users\Sunny_Future\AppData\Roaming\Python\Python36\site-packages\django\contrib\sessions\backends\db.py", line 43, in load
    s = self._get_session_from_db()
  File "C:\Users\Sunny_Future\AppData\Roaming\Python\Python36\site-packages\django\contrib\sessions\backends\db.py", line 34, in _get_session_from_db
    expire_date__gt=timezone.now()
  File "C:\Users\Sunny_Future\AppData\Roaming\Python\Python36\site-packages\django\db\models\manager.py", line 85, in manager_method
    return getattr(self.get_queryset(), name)(*args, **kwargs)
  File "C:\Users\Sunny_Future\AppData\Roaming\Python\Python36\site-packages\django\db\models\query.py", line 425, in get
    num = len(clone)
  File "C:\Users\Sunny_Future\AppData\Roaming\Python\Python36\site-packages\django\db\models\query.py", line 269, in __len__
    self._fetch_all()
  File "C:\Users\Sunny_Future\AppData\Roaming\Python\Python36\site-packages\django\db\models\query.py", line 1308, in _fetch_all
    self._result_cache = list(self._iterable_class(self))
  File "C:\Users\Sunny_Future\AppData\Roaming\Python\Python36\site-packages\django\db\models\query.py", line 53, in __iter__
    results = compiler.execute_sql(chunked_fetch=self.chunked_fetch, chunk_size=self.chunk_size)
  File "C:\Users\Sunny_Future\AppData\Roaming\Python\Python36\site-packages\django\db\models\sql\compiler.py", line 1154, in execute_sql
    cursor = self.connection.cursor()
  File "C:\Users\Sunny_Future\AppData\Roaming\Python\Python36\site-packages\django\utils\asyncio.py", line 26, in inner
    return func(*args, **kwargs)
  File "C:\Users\Sunny_Future\AppData\Roaming\Python\Python36\site-packages\django\db\backends\base\base.py", line 259, in cursor
    return self._cursor()
  File "C:\Users\Sunny_Future\AppData\Roaming\Python\Python36\site-packages\django\db\backends\base\base.py", line 235, in _cursor
    self.ensure_connection()
  File "C:\Users\Sunny_Future\AppData\Roaming\Python\Python36\site-packages\django\utils\asyncio.py", line 26, in inner
    return func(*args, **kwargs)
  File "C:\Users\Sunny_Future\AppData\Roaming\Python\Python36\site-packages\django\db\backends\base\base.py", line 219, in ensure_connection
    self.connect()
  File "C:\Users\Sunny_Future\AppData\Roaming\Python\Python36\site-packages\django\db\utils.py", line 90, in __exit__
    raise dj_exc_value.with_traceback(traceback) from exc_value
  File "C:\Users\Sunny_Future\AppData\Roaming\Python\Python36\site-packages\django\db\backends\base\base.py", line 219, in ensure_connection
    self.connect()
  File "C:\Users\Sunny_Future\AppData\Roaming\Python\Python36\site-packages\django\utils\asyncio.py", line 26, in inner
    return func(*args, **kwargs)
  File "C:\Users\Sunny_Future\AppData\Roaming\Python\Python36\site-packages\django\db\backends\base\base.py", line 200, in connect
    self.connection = self.get_new_connection(conn_params)
  File "C:\Users\Sunny_Future\AppData\Roaming\Python\Python36\site-packages\django\utils\asyncio.py", line 26, in inner
    return func(*args, **kwargs)
  File "C:\Users\Sunny_Future\AppData\Roaming\Python\Python36\site-packages\django\db\backends\mysql\base.py", line 234, in get_new_connection
    return Database.connect(**conn_params)
  File "C:\Users\Sunny_Future\AppData\Roaming\Python\Python36\site-packages\pymysql\connections.py", line 353, in __init__
    self.connect()
  File "C:\Users\Sunny_Future\AppData\Roaming\Python\Python36\site-packages\pymysql\connections.py", line 664, in connect
    raise exc
django.db.utils.OperationalError: (2003, "Can't connect to MySQL server on '192.168.137.11' (timed out)")
ERROR 2021-01-30 20:01:55,377 basehttp 157 "GET /xadmin/host/hosts/ HTTP/1.1" 500 286171
INFO 2021-01-30 20:02:03,153 basehttp 157 "GET /xadmin/host/hosts/ HTTP/1.1" 200 23761
INFO 2021-01-30 20:02:03,181 basehttp 157 "GET /xadmin/jsi18n/ HTTP/1.1" 200 7732
INFO 2021-01-30 20:02:12,263 basehttp 157 "GET /xadmin/users/user/ HTTP/1.1" 200 33621
INFO 2021-01-30 20:02:12,285 basehttp 157 "GET /xadmin/jsi18n/ HTTP/1.1" 200 7732
INFO 2021-01-30 20:02:14,896 basehttp 157 "GET /xadmin/host/hosts/ HTTP/1.1" 200 23761
ERROR 2021-01-30 20:02:14,897 basehttp 157 "GET /xadmin/host/hosts/ HTTP/1.1" 500 59
INFO 2021-01-30 20:02:22,462 basehttp 157 "GET /xadmin/xadmin/log/ HTTP/1.1" 200 39470
INFO 2021-01-30 20:02:22,484 basehttp 157 "GET /static/xadmin/vendor/bootstrap-datepicker/css/datepicker.css HTTP/1.1" 304 0
INFO 2021-01-30 20:02:22,489 basehttp 157 "GET /static/xadmin/vendor/select2/select2.css HTTP/1.1" 304 0
INFO 2021-01-30 20:02:22,490 basehttp 157 "GET /static/xadmin/vendor/selectize/selectize.bootstrap3.css HTTP/1.1" 304 0
INFO 2021-01-30 20:02:22,490 basehttp 157 "GET /static/xadmin/vendor/selectize/selectize.css HTTP/1.1" 304 0
INFO 2021-01-30 20:02:22,492 basehttp 157 "GET /static/xadmin/vendor/selectize/selectize.js HTTP/1.1" 304 0
INFO 2021-01-30 20:02:22,493 basehttp 157 "GET /static/xadmin/vendor/bootstrap-datepicker/js/bootstrap-datepicker.js HTTP/1.1" 304 0
INFO 2021-01-30 20:02:22,495 basehttp 157 "GET /static/xadmin/js/xadmin.widget.datetime.js HTTP/1.1" 304 0
INFO 2021-01-30 20:02:22,497 basehttp 157 "GET /static/xadmin/vendor/select2/select2.js HTTP/1.1" 304 0
INFO 2021-01-30 20:02:22,498 basehttp 157 "GET /static/xadmin/js/xadmin.widget.select.js HTTP/1.1" 304 0
INFO 2021-01-30 20:02:22,500 basehttp 157 "GET /static/xadmin/vendor/select2/select2_locale_zh-Hans.js HTTP/1.1" 304 0
INFO 2021-01-30 20:02:22,503 basehttp 157 "GET /xadmin/jsi18n/ HTTP/1.1" 200 7732
INFO 2021-01-30 20:40:30,357 autoreload 240 F:\文档\code\pythonCode\hippo\hippo_api\hippo_api\settings\dev.py changed, reloading.
INFO 2021-01-30 20:40:30,458 autoreload 240 F:\文档\code\pythonCode\hippo\hippo_api\hippo_api\settings\dev.py changed, reloading.
INFO 2021-01-30 20:40:31,838 autoreload 617 Watching for file changes with StatReloader
